Workbook

Sheet Como usar
A1: Controle de notificações da fiscalização (MTE e MPT)
A3: 1. Notificações: cada notificação recebida é uma linha, ligada ao cliente.
A4: 2. Itens: cada documento ou exigência pedido é uma linha, com o código da aba Catálogo.
A5: O documento padrão e o responsável aparecem sozinhos a partir do código.
A6: 3. Catálogo: lista padrão de documentos. Use sempre o mesmo código para o mesmo documento;
A7: é isso que permite comparar o que os fiscais mais pedem. Documento novo: acrescente uma linha.
A8: 3b. Por empresa: escolha a empresa na célula amarela e veja só os itens dela (dá para filtrar por responsável e status).
A9: Nas abas Itens e Notificações também há filtro na coluna Cliente (setinha no cabeçalho).
A10: 4. Painel: ranking dos documentos mais pedidos, divisão por responsável e por cliente (atualiza sozinho).
A12: Responsáveis:
A13: • Assessoria SST: PGR, PCMSO, ASO, LTCAT, AEP, treinamentos, NR-12 (inventário), análise de acidentes.
A14: • Empresa – RH/DP: registro, relação de empregados, ponto (AFD/AEJ/espelho), estagiários, aprendizes, CCT.
... A20: Status 'A confirmar' = notificação já vencida cujo atendimento não foi informado.

Sheet Painel
A1: Painel – o que a fiscalização mais pede
A2: Atualiza sozinho a partir das abas Itens e Notificações.
A4: # | B4: Documento | C4: Responsável | D4: Nº de notificações | E4: Pendentes | G4: Responsável | H4: Itens | I4: Pendentes / a confirmar | J4: % dos itens
A5: 1 | B5: =INDEX(Catálogo!$B$2:$B$200,MATCH(LARGE(Catálogo!$I$2:$I$200,1),Catálogo!$I$2:$I$200,0)) | C5: =INDEX(Catálogo!$D$2:$D$200,MATCH(LARGE(Catálogo!$I$2:$I$200,1),Catálogo!$I$2:$I$200,0)) | D5: =INDEX(Catálogo!$F$2:$F$200,MATCH(LARGE(Catálogo!$I$2:$I$200,1),Catálogo!$I$2:$I$200,0)) | E5: =INDEX(Catálogo!$H$2:$H$200,MATCH(LARGE(Catálogo!$I$2:$I$200,1),Catálogo!$I$2:$I$200,0)) | G5: Assessoria SST | H5: =COUNTIF(Itens!$F:$F,G5) | I5: =COUNTIFS(Itens!$F:$F,G5,Itens!$I:$I,"Pendente")+COUNTIFS(Itens!$F:$F,G5,Itens!$I:$I,"Em andamento")+COUNTIFS(Itens!$F:$F,G5,Itens!$I:$I,"A confirmar") | J5: =IF(SUM($H$5:$H$9)=0,0,H5/SUM($H$5:$H$9))
A6: 2 | B6: =INDEX(Catálogo!$B$2:$B$200,MATCH(LARGE(Catálogo!$I$2:$I$200,2),Catálogo!$I$2:$I$200,0)) | C6: =INDEX(Catálogo!$D$2:$D$200,MATCH(LARGE(Catálogo!$I$2:$I$200,2),Catálogo!$I$2:$I$200,0)) | D6: =INDEX(Catálogo!$F$2:$F$200,MATCH(LARGE(Catálogo!$I$2:$I$200,2),Catálogo!$I$2:$I$200,0)) | E6: =INDEX(Catálogo!$H$2:$H$200,MATCH(LARGE(Catálogo!$I$2:$I$200,2),Catálogo!$I$2:$I$200,0)) | G6: Empresa – RH/DP | H6: =COUNTIF(Itens!$F:$F,G6) | I6: =COUNTIFS(Itens!$F:$F,G6,Itens!$I:$I,"Pendente")+COUNTIFS(Itens!$F:$F,G6,Itens!$I:$I,"Em andamento")+COUNTIFS(Itens!$F:$F,G6,Itens!$I:$I,"A confirmar") | J6: =IF(SUM($H$5:$H$9)=0,0,H6/SUM($H$5:$H$9))
A7: 3 | B7: =INDEX(Catálogo!$B$2:$B$200,MATCH(LARGE(Catálogo!$I$2:$I$200,3),Catálogo!$I$2:$I$200,0)) | C7: =INDEX(Catálogo!$D$2:$D$200,MATCH(LARGE(Catálogo!$I$2:$I$200,3),Catálogo!$I$2:$I$200,0)) | D7: =INDEX(Catálogo!$F$2:$F$200,MATCH(LARGE(Catálogo!$I$2:$I$200,3),Catálogo!$I$2:$I$200,0)) | E7: =INDEX(Catálogo!$H$2:$H$200,MATCH(LARGE(Catálogo!$I$2:$I$200,3),Catálogo!$I$2:$I$200,0)) | G7: Empresa – Financeiro | H7: =COUNTIF(Itens!$F:$F,G7) | I7: =COUNTIFS(Itens!$F:$F,G7,Itens!$I:$I,"Pendente")+COUNTIFS(Itens!$F:$F,G7,Itens!$I:$I,"Em andamento")+COUNTIFS(Itens!$F:$F,G7,Itens!$I:$I,"A confirmar") | J7: =IF(SUM($H$5:$H$9)=0,0,H7/SUM($H$5:$H$9))
A8: 4 | B8: =INDEX(Catálogo!$B$2:$B$200,MATCH(LARGE(Catálogo!$I$2:$I$200,4),Catálogo!$I$2:$I$200,0)) | C8: =INDEX(Catálogo!$D$2:$D$200,MATCH(LARGE(Catálogo!$I$2:$I$200,4),Catálogo!$I$2:$I$200,0)) | D8: =INDEX(Catálogo!$F$2:$F$200,MATCH(LARGE(Catálogo!$I$2:$I$200,4),Catálogo!$I$2:$I$200,0)) | E8: =INDEX(Catálogo!$H$2:$H$200,MATCH(LARGE(Catálogo!$I$2:$I$200,4),Catálogo!$I$2:$I$200,0)) | G8: Empresa – Operação/Manutenção | H8: =COUNTIF(Itens!$F:$F,G8) | I8: =COUNTIFS(Itens!$F:$F,G8,Itens!$I:$I,"Pendente")+COUNTIFS(Itens!$F:$F,G8,Itens!$I:$I,"Em andamento")+COUNTIFS(Itens!$F:$F,G8,Itens!$I:$I,"A confirmar") | J8: =IF(SUM($H$5:$H$9)=0,0,H8/SUM($H$5:$H$9))
A9: 5 | B9: =INDEX(Catálogo!$B$2:$B$200,MATCH(LARGE(Catálogo!$I$2:$I$200,5),Catálogo!$I$2:$I$200,0)) | C9: =INDEX(Catálogo!$D$2:$D$200,MATCH(LARGE(Catálogo!$I$2:$I$200,5),Catálogo!$I$2:$I$200,0)) | D9: =INDEX(Catálogo!$F$2:$F$200,MATCH(LARGE(Catálogo!$I$2:$I$200,5),Catálogo!$I$2:$I$200,0)) | E9: =INDEX(Catálogo!$H$2:$H$200,MATCH(LARGE(Catálogo!$I$2:$I$200,5),Catálogo!$I$2:$I$200,0)) | G9: Compartilhado (Empresa + SST) | H9: =COUNTIF(Itens!$F:$F,G9) | I9: =COUNTIFS(Itens!$F:$F,G9,Itens!$I:$I,"Pendente")+COUNTIFS(Itens!$F:$F,G9,Itens!$I:$I,"Em andamento")+COUNTIFS(Itens!$F:$F,G9,Itens!$I:$I,"A confirmar") | J9: =IF(SUM($H$5:$H$9)=0,0,H9/SUM($H$5:$H$9))
A10: 6 | B10: =INDEX(Catálogo!$B$2:$B$200,MATCH(LARGE(Catálogo!$I$2:$I$200,6),Catálogo!$I$2:$I$200,0)) | C10: =INDEX(Catálogo!$D$2:$D$200,MATCH(LARGE(Catálogo!$I$2:$I$200,6),Catálogo!$I$2:$I$200,0)) | D10: =INDEX(Catálogo!$F$2:$F$200,MATCH(LARGE(Catálogo!$I$2:$I$200,6),Catálogo!$I$2:$I$200,0)) | E10: =INDEX(Catálogo!$H$2:$H$200,MATCH(LARGE(Catálogo!$I$2:$I$200,6),Catálogo!$I$2:$I$200,0))
A11: 7 | B11: =INDEX(Catálogo!$B$2:$B$200,MATCH(LARGE(Catálogo!$I$2:$I$200,7),Catálogo!$I$2:$I$200,0)) | C11: =INDEX(Catálogo!$D$2:$D$200,MATCH(LARGE(Catálogo!$I$2:$I$200,7),Catálogo!$I$2:$I$200,0)) | D11: =INDEX(Catálogo!$F$2:$F$200,MATCH(LARGE(Catálogo!$I$2:$I$200,7),Catálogo!$I$2:$I$200,0)) | E11: =INDEX(Catálogo!$H$2:$H$200,MATCH(LARGE(Catálogo!$I$2:$I$200,7),Catálogo!$I$2:$I$200,0)) | G11: Cliente novo: escreva o nome numa linha vazia abaixo (vale para o filtro da aba 'Por empresa').
A12: 8 | B12: =INDEX(Catálogo!$B$2:$B$200,MATCH(LARGE(Catálogo!$I$2:$I$200,8),Catálogo!$I$2:$I$200,0)) | C12: =INDEX(Catálogo!$D$2:$D$200,MATCH(LARGE(Catálogo!$I$2:$I$200,8),Catálogo!$I$2:$I$200,0)) | D12: =INDEX(Catálogo!$F$2:$F$200,MATCH(LARGE(Catálogo!$I$2:$I$200,8),Catálogo!$I$2:$I$200,0)) | E12: =INDEX(Catálogo!$H$2:$H$200,MATCH(LARGE(Catálogo!$I$2:$I$200,8),Catálogo!$I$2:$I$200,0)) | G12: Cliente | H12: Notificações | I12: Itens | J12: Pendentes / a confirmar
A13: 9 | B13: =INDEX(Catálogo!$B$2:$B$200,MATCH(LARGE(Catálogo!$I$2:$I$200,9),Catálogo!$I$2:$I$200,0)) | C13: =INDEX(Catálogo!$D$2:$D$200,MATCH(LARGE(Catálogo!$I$2:$I$200,9),Catálogo!$I$2:$I$200,0)) | D13: =INDEX(Catálogo!$F$2:$F$200,MATCH(LARGE(Catálogo!$I$2:$I$200,9),Catálogo!$I$2:$I$200,0)) | E13: =INDEX(Catálogo!$H$2:$H$200,MATCH(LARGE(Catálogo!$I$2:$I$200,9),Catálogo!$I$2:$I$200,0)) | G13: Rede Total (Mix Concórdia) | H13: =COUNTIF(Notificações!$B:$B,G13) | I13: =COUNTIF(Itens!$B:$B,G13) | J13: =SUMIF(Notificações!$B:$B,G13,Notificações!$R:$R)
A14: 10 | B14: =INDEX(Catálogo!$B$2:$B$200,MATCH(LARGE(Catálogo!$I$2:$I$200,10),Catálogo!$I$2:$I$200,0)) | C14: =INDEX(Catálogo!$D$2:$D$200,MATCH(LARGE(Catálogo!$I$2:$I$200,10),Catálogo!$I$2:$I$200,0)) | D14: =INDEX(Catálogo!$F$2:$F$200,MATCH(LARGE(Catálogo!$I$2:$I$200,10),Catálogo!$I$2:$I$200,0)) | E14: =INDEX(Catálogo!$H$2:$H$200,MATCH(LARGE(Catálogo!$I$2:$I$200,10),Catálogo!$I$2:$I$200,0)) | G14: Mix Boca do Rio | H14: =COUNTIF(Notificações!$B:$B,G14) | I14: =COUNTIF(Itens!$B:$B,G14) | J14: =SUMIF(Notificações!$B:$B,G14,Notificações!$R:$R)
A15: 11 | B15: =INDEX(Catálogo!$B$2:$B$200,MATCH(LARGE(Catálogo!$I$2:$I$200,11),Catálogo!$I$2:$I$200,0)) | C15: =INDEX(Catálogo!$D$2:$D$200,MATCH(LARGE(Catálogo!$I$2:$I$200,11),Catálogo!$I$2:$I$200,0)) | D15: =INDEX(Catálogo!$F$2:$F$200,MATCH(LARGE(Catálogo!$I$2:$I$200,11),Catálogo!$I$2:$I$200,0)) | E15: =INDEX(Catálogo!$H$2:$H$200,MATCH(LARGE(Catálogo!$I$2:$I$200,11),Catálogo!$I$2:$I$200,0)) | G15: Mix Bahia – Lauro de Freitas | H15: =COUNTIF(Notificações!$B:$B,G15) | I15: =COUNTIF(Itens!$B:$B,G15) | J15: =SUMIF(Notificações!$B:$B,G15,Notificações!$R:$R)
A16: 12 | B16: =INDEX(Catálogo!$B$2:$B$200,MATCH(LARGE(Catálogo!$I$2:$I$200,12),Catálogo!$I$2:$I$200,0)) | C16: =INDEX(Catálogo!$D$2:$D$200,MATCH(LARGE(Catálogo!$I$2:$I$200,12),Catálogo!$I$2:$I$200,0)) | D16: =INDEX(Catálogo!$F$2:$F$200,MATCH(LARGE(Catálogo!$I$2:$I$200,12),Catálogo!$I$2:$I$200,0)) | E16: =INDEX(Catálogo!$H$2:$H$200,MATCH(LARGE(Catálogo!$I$2:$I$200,12),Catálogo!$I$2:$I$200,0)) | G16: Super Diesel | H16: =COUNTIF(Notificações!$B:$B,G16) | I16: =COUNTIF(Itens!$B:$B,G16) | J16: =SUMIF(Notificações!$B:$B,G16,Notificações!$R:$R)
A17: 13 | B17: =INDEX(Catálogo!$B$2:$B$200,MATCH(LARGE(Catálogo!$I$2:$I$200,13),Catálogo!$I$2:$I$200,0)) | C17: =INDEX(Catálogo!$D$2:$D$200,MATCH(LARGE(Catálogo!$I$2:$I$200,13),Catálogo!$I$2:$I$200,0)) | D17: =INDEX(Catálogo!$F$2:$F$200,MATCH(LARGE(Catálogo!$I$2:$I$200,13),Catálogo!$I$2:$I$200,0)) | E17: =INDEX(Catálogo!$H$2:$H$200,MATCH(LARGE(Catálogo!$I$2:$I$200,13),Catálogo!$I$2:$I$200,0)) | H17: =IF(G17="","",COUNTIF(Notificações!$B:$B,G17)) | I17: =IF(G17="","",COUNTIF(Itens!$B:$B,G17)) | J17: =IF(G17="","",SUMIF(Notificações!$B:$B,G17,Notificações!$R:$R))
A18: 14 | B18: =INDEX(Catálogo!$B$2:$B$200,MATCH(LARGE(Catálogo!$I$2:$I$200,14),Catálogo!$I$2:$I$200,0)) | C18: =INDEX(Catálogo!$D$2:$D$200,MATCH(LARGE(Catálogo!$I$2:$I$200,14),Catálogo!$I$2:$I$200,0)) | D18: =INDEX(Catálogo!$F$2:$F$200,MATCH(LARGE(Catálogo!$I$2:$I$200,14),Catálogo!$I$2:$I$200,0)) | E18: =INDEX(Catálogo!$H$2:$H$200,MATCH(LARGE(Catálogo!$I$2:$I$200,14),Catálogo!$I$2:$I$200,0)) | H18: =IF(G18="","",COUNTIF(Notificações!$B:$B,G18)) | I18: =IF(G18="","",COUNTIF(Itens!$B:$B,G18)) | J18: =IF(G18="","",SUMIF(Notificações!$B:$B,G18,Notificações!$R:$R))
A19: 15 | B19: =INDEX(Catálogo!$B$2:$B$200,MATCH(LARGE(Catálogo!$I$2:$I$200,15),Catálogo!$I$2:$I$200,0)) | C19: =INDEX(Catálogo!$D$2:$D$200,MATCH(LARGE(Catálogo!$I$2:$I$200,15),Catálogo!$I$2:$I$200,0)) | D19: =INDEX(Catálogo!$F$2:$F$200,MATCH(LARGE(Catálogo!$I$2:$I$200,15),Catálogo!$I$2:$I$200,0)) | E19: =INDEX(Catálogo!$H$2:$H$200,MATCH(LARGE(Catálogo!$I$2:$I$200,15),Catálogo!$I$2:$I$200,0)) | H19: =IF(G19="","",COUNTIF(Notificações!$B:$B,G19)) | I19: =IF(G19="","",COUNTIF(Itens!$B:$B,G19)) | J19: =IF(G19="","",SUMIF(Notificações!$B:$B,G19,Notificações!$R:$R))
A20: Ranking pelo nº de notificações em que o documento aparece. Códigos novos no Catálogo entram sozinhos (até 199 códigos). | H20: =IF(G20="","",COUNTIF(Notificações!$B:$B,G20)) | I20: =IF(G20="","",COUNTIF(Itens!$B:$B,G20)) | J20: =IF(G20="","",SUMIF(Notificações!$B:$B,G20,Notificações!$R:$R))
H21: =IF(G21="","",COUNTIF(Notificações!$B:$B,G21)) | I21: =IF(G21="","",COUNTIF(Itens!$B:$B,G21)) | J21: =IF(G21="","",SUMIF(Notificações!$B:$B,G21,Notificações!$R:$R))
H22: =IF(G22="","",COUNTIF(Notificações!$B:$B,G22)) | I22: =IF(G22="","",COUNTIF(Itens!$B:$B,G22)) | J22: =IF(G22="","",SUMIF(Notificações!$B:$B,G22,Notificações!$R:$R))
H23: =IF(G23="","",COUNTIF(Notificações!$B:$B,G23)) | I23: =IF(G23="","",COUNTIF(Itens!$B:$B,G23)) | J23: =IF(G23="","",SUMIF(Notificações!$B:$B,G23,Notificações!$R:$R))
H24: =IF(G24="","",COUNTIF(Notificações!$B:$B,G24)) | I24: =IF(G24="","",COUNTIF(Itens!$B:$B,G24)) | J24: =IF(G24="","",SUMIF(Notificações!$B:$B,G24,Notificações!$R:$R))
H25: =IF(G25="","",COUNTIF(Notificações!$B:$B,G25)) | I25: =IF(G25="","",COUNTIF(Itens!$B:$B,G25)) | J25: =IF(G25="","",SUMIF(Notificações!$B:$B,G25,Notificações!$R:$R))
H26: =IF(G26="","",COUNTIF(Notificações!$B:$B,G26)) | I26: =IF(G26="","",COUNTIF(Itens!$B:$B,G26)) | J26: =IF(G26="","",SUMIF(Notificações!$B:$B,G26,Notificações!$R:$R))
H27: =IF(G27="","",COUNTIF(Notificações!$B:$B,G27)) | I27: =IF(G27="","",COUNTIF(Itens!$B:$B,G27)) | J27: =IF(G27="","",SUMIF(Notificações!$B:$B,G27,Notificações!$R:$R))
H28: =IF(G28="","",COUNTIF(Notificações!$B:$B,G28)) | I28: =IF(G28="","",COUNTIF(Itens!$B:$B,G28)) | J28: =IF(G28="","",SUMIF(Notificações!$B:$B,G28,Notificações!$R:$R))
H29: =IF(G29="","",COUNTIF(Notificações!$B:$B,G29)) | I29: =IF(G29="","",COUNTIF(Itens!$B:$B,G29)) | J29: =IF(G29="","",SUMIF(Notificações!$B:$B,G29,Notificações!$R:$R))
H30: =IF(G30="","",COUNTIF(Notificações!$B:$B,G30)) | I30: =IF(G30="","",COUNTIF(Itens!$B:$B,G30)) | J30: =IF(G30="","",SUMIF(Notificações!$B:$B,G30,Notificações!$R:$R))
H31: =IF(G31="","",COUNTIF(Notificações!$B:$B,G31)) | I31: =IF(G31="","",COUNTIF(Itens!$B:$B,G31)) | J31: =IF(G31="","",SUMIF(Notificações!$B:$B,G31,Notificações!$R:$R))
H32: =IF(G32="","",COUNTIF(Notificações!$B:$B,G32)) | I32: =IF(G32="","",COUNTIF(Itens!$B:$B,G32)) | J32: =IF(G32="","",SUMIF(Notificações!$B:$B,G32,Notificações!$R:$R))

Sheet Por empresa
A1: Itens por empresa
A2: Empresa: | B2: Rede Total (Mix Concórdia) | C2: ◄ escolha a empresa na lista
A4: Notificações | B4: Itens pedidos | C4: Pendentes / a confirmar | D4: Entregues | F4: Responsável | G4: Itens | H4: Pendentes
A5: =COUNTIF(Notificações!$B:$B,$B$2) | B5: =COUNTIF(Itens!$B:$B,$B$2) | C5: =COUNTIFS(Itens!$B:$B,$B$2,Itens!$I:$I,"Pendente")+COUNTIFS(Itens!$B:$B,$B$2,Itens!$I:$I,"Em andamento")+COUNTIFS(Itens!$B:$B,$B$2,Itens!$I:$I,"A confirmar") | D5: =COUNTIFS(Itens!$B:$B,$B$2,Itens!$I:$I,"Entregue") | F5: Assessoria SST | G5: =COUNTIFS(Itens!$B:$B,$B$2,Itens!$F:$F,F5) | H5: =COUNTIFS(Itens!$B:$B,$B$2,Itens!$F:$F,F5,Itens!$I:$I,"Pendente")+COUNTIFS(Itens!$B:$B,$B$2,Itens!$F:$F,F5,Itens!$I:$I,"Em andamento")+COUNTIFS(Itens!$B:$B,$B$2,Itens!$F:$F,F5,Itens!$I:$I,"A confirmar")
F6: Empresa – RH/DP | G6: =COUNTIFS(Itens!$B:$B,$B$2,Itens!$F:$F,F6) | H6: =COUNTIFS(Itens!$B:$B,$B$2,Itens!$F:$F,F6,Itens!$I:$I,"Pendente")+COUNTIFS(Itens!$B:$B,$B$2,Itens!$F:$F,F6,Itens!$I:$I,"Em andamento")+COUNTIFS(Itens!$B:$B,$B$2,Itens!$F:$F,F6,Itens!$I:$I,"A confirmar")
F7: Empresa – Financeiro | G7: =COUNTIFS(Itens!$B:$B,$B$2,Itens!$F:$F,F7) | H7: =COUNTIFS(Itens!$B:$B,$B$2,Itens!$F:$F,F7,Itens!$I:$I,"Pendente")+COUNTIFS(Itens!$B:$B,$B$2,Itens!$F:$F,F7,Itens!$I:$I,"Em andamento")+COUNTIFS(Itens!$B:$B,$B$2,Itens!$F:$F,F7,Itens!$I:$I,"A confirmar")
F8: Empresa – Operação/Manutenção | G8: =COUNTIFS(Itens!$B:$B,$B$2,Itens!$F:$F,F8) | H8: =COUNTIFS(Itens!$B:$B,$B$2,Itens!$F:$F,F8,Itens!$I:$I,"Pendente")+COUNTIFS(Itens!$B:$B,$B$2,Itens!$F:$F,F8,Itens!$I:$I,"Em andamento")+COUNTIFS(Itens!$B:$B,$B$2,Itens!$F:$F,F8,Itens!$I:$I,"A confirmar")
F9: Compartilhado (Empresa + SST) | G9: =COUNTIFS(Itens!$B:$B,$B$2,Itens!$F:$F,F9) | H9: =COUNTIFS(Itens!$B:$B,$B$2,Itens!$F:$F,F9,Itens!$I:$I,"Pendente")+COUNTIFS(Itens!$B:$B,$B$2,Itens!$F:$F,F9,Itens!$I:$I,"Em andamento")+COUNTIFS(Itens!$B:$B,$B$2,Itens!$F:$F,F9,Itens!$I:$I,"A confirmar")
A12: Notificação | B12: Item nº | C12: Documento padrão | D12: Responsável | E12: Texto da notificação | F12: Status | G12: Período pedido | H12: Data de entrega | I12: Observações
A13: =IFERROR(IF(INDEX(Itens!$A$2:$A$501,MATCH(1,Itens!$M$2:$M$501,0))="","",INDEX(Itens!$A$2:$A$501,MATCH(1,Itens!$M$2:$M$501,0))),"") | B13: =IFERROR(IF(INDEX(Itens!$C$2:$C$501,MATCH(1,Itens!$M$2:$M$501,0))="","",INDEX(Itens!$C$2:$C$501,MATCH(1,Itens!$M$2:$M$501,0))),"") | C13: =IFERROR(IF(INDEX(Itens!$E$2:$E$501,MATCH(1,Itens!$M$2:$M$501,0))="","",INDEX(Itens!$E$2:$E$501,MATCH(1,Itens!$M$2:$M$501,0))),"") | D13: =IFERROR(IF(INDEX(Itens!$F$2:$F$501,MATCH(1,Itens!$M$2:$M$501,0))="","",INDEX(Itens!$F$2:$F$501,MATCH(1,Itens!$M$2:$M$501,0))),"") | E13: =IFERROR(IF(INDEX(Itens!$G$2:$G$501,MATCH(1,Itens!$M$2:$M$501,0))="","",INDEX(Itens!$G$2:$G$501,MATCH(1,Itens!$M$2:$M$501,0))),"") | F13: =IFERROR(IF(INDEX(Itens!$I$2:$I$501,MATCH(1,Itens!$M$2:$M$501,0))="","",INDEX(Itens!$I$2:$I$501,MATCH(1,Itens!$M$2:$M$501,0))),"") | G13: =IFERROR(IF(INDEX(Itens!$J$2:$J$501,MATCH(1,Itens!$M$2:$M$501,0))="","",INDEX(Itens!$J$2:$J$501,MATCH(1,Itens!$M$2:$M$501,0))),"") | H13: =IFERROR(IF(INDEX(Itens!$K$2:$K$501,MATCH(1,Itens!$M$2:$M$501,0))="","",INDEX(Itens!$K$2:$K$501,MATCH(1,Itens!$M$2:$M$501,0))),"") | I13: =IFERROR(IF(INDEX(Itens!$L$2:$L$501,MATCH(1,Itens!$M$2:$M$501,0))="","",INDEX(Itens!$L$2:$L$501,MATCH(1,Itens!$M$2:$M$501,0))),"")
A14: =IFERROR(IF(INDEX(Itens!$A$2:$A$501,MATCH(2,Itens!$M$2:$M$501,0))="","",INDEX(Itens!$A$2:$A$501,MATCH(2,Itens!$M$2:$M$501,0))),"") | B14: =IFERROR(IF(INDEX(Itens!$C$2:$C$501,MATCH(2,Itens!$M$2:$M$501,0))="","",INDEX(Itens!$C$2:$C$501,MATCH(2,Itens!$M$2:$M$501,0))),"") | C14: =IFERROR(IF(INDEX(Itens!$E$2:$E$501,MATCH(2,Itens!$M$2:$M$501,0))="","",INDEX(Itens!$E$2:$E$501,MATCH(2,Itens!$M$2:$M$501,0))),"") | D14: =IFERROR(IF(INDEX(Itens!$F$2:$F$501,MATCH(2,Itens!$M$2:$M$501,0))="","",INDEX(Itens!$F$2:$F$501,MATCH(2,Itens!$M$2:$M$501,0))),"") | E14: =IFERROR(IF(INDEX(Itens!$G$2:$G$501,MATCH(2,Itens!$M$2:$M$501,0))="","",INDEX(Itens!$G$2:$G$501,MATCH(2,Itens!$M$2:$M$501,0))),"") | F14: =IFERROR(IF(INDEX(Itens!$I$2:$I$501,MATCH(2,Itens!$M$2:$M$501,0))="","",INDEX(Itens!$I$2:$I$501,MATCH(2,Itens!$M$2:$M$501,0))),"") | G14: =IFERROR(IF(INDEX(Itens!$J$2:$J$501,MATCH(2,Itens!$M$2:$M$501,0))="","",INDEX(Itens!$J$2:$J$501,MATCH(2,Itens!$M$2:$M$501,0))),"") | H14: =IFERROR(IF(INDEX(Itens!$K$2:$K$501,MATCH(2,Itens!$M$2:$M$501,0))="","",INDEX(Itens!$K$2:$K$501,MATCH(2,Itens!$M$2:$M$501,0))),"") | I14: =IFERROR(IF(INDEX(Itens!$L$2:$L$501,MATCH(2,Itens!$M$2:$M$501,0))="","",INDEX(Itens!$L$2:$L$501,MATCH(2,Itens!$M$2:$M$501,0))),"")
A15: =IFERROR(IF(INDEX(Itens!$A$2:$A$501,MATCH(3,Itens!$M$2:$M$501,0))="","",INDEX(Itens!$A$2:$A$501,MATCH(3,Itens!$M$2:$M$501,0))),"") | B15: =IFERROR(IF(INDEX(Itens!$C$2:$C$501,MATCH(3,Itens!$M$2:$M$501,0))="","",INDEX(Itens!$C$2:$C$501,MATCH(3,Itens!$M$2:$M$501,0))),"") | C15: =IFERROR(IF(INDEX(Itens!$E$2:$E$501,MATCH(3,Itens!$M$2:$M$501,0))="","",INDEX(Itens!$E$2:$E$501,MATCH(3,Itens!$M$2:$M$501,0))),"") | D15: =IFERROR(IF(INDEX(Itens!$F$2:$F$501,MATCH(3,Itens!$M$2:$M$501,0))="","",INDEX(Itens!$F$2:$F$501,MATCH(3,Itens!$M$2:$M$501,0))),"") | E15: =IFERROR(IF(INDEX(Itens!$G$2:$G$501,MATCH(3,Itens!$M$2:$M$501,0))="","",INDEX(Itens!$G$2:$G$501,MATCH(3,Itens!$M$2:$M$501,0))),"") | F15: =IFERROR(IF(INDEX(Itens!$I$2:$I$501,MATCH(3,Itens!$M$2:$M$501,0))="","",INDEX(Itens!$I$2:$I$501,MATCH(3,Itens!$M$2:$M$501,0))),"") | G15: =IFERROR(IF(INDEX(Itens!$J$2:$J$501,MATCH(3,Itens!$M$2:$M$501,0))="","",INDEX(Itens!$J$2:$J$501,MATCH(3,Itens!$M$2:$M$501,0))),"") | H15: =IFERROR(IF(INDEX(Itens!$K$2:$K$501,MATCH(3,Itens!$M$2:$M$501,0))="","",INDEX(Itens!$K$2:$K$501,MATCH(3,Itens!$M$2:$M$501,0))),"") | I15: =IFERROR(IF(INDEX(Itens!$L$2:$L$501,MATCH(3,Itens!$M$2:$M$501,0))="","",INDEX(Itens!$L$2:$L$501,MATCH(3,Itens!$M$2:$M$501,0))),"")
A16: =IFERROR(IF(INDEX(Itens!$A$2:$A$501,MATCH(4,Itens!$M$2:$M$501,0))="","",INDEX(Itens!$A$2:$A$501,MATCH(4,Itens!$M$2:$M$501,0))),"") | B16: =IFERROR(IF(INDEX(Itens!$C$2:$C$501,MATCH(4,Itens!$M$2:$M$501,0))="","",INDEX(Itens!$C$2:$C$501,MATCH(4,Itens!$M$2:$M$501,0))),"") | C16: =IFERROR(IF(INDEX(Itens!$E$2:$E$501,MATCH(4,Itens!$M$2:$M$501,0))="","",INDEX(Itens!$E$2:$E$501,MATCH(4,Itens!$M$2:$M$501,0))),"") | D16: =IFERROR(IF(INDEX(Itens!$F$2:$F$501,MATCH(4,Itens!$M$2:$M$501,0))="","",INDEX(Itens!$F$2:$F$501,MATCH(4,Itens!$M$2:$M$501,0))),"") | E16: =IFERROR(IF(INDEX(Itens!$G$2:$G$501,MATCH(4,Itens!$M$2:$M$501,0))="","",INDEX(Itens!$G$2:$G$501,MATCH(4,Itens!$M$2:$M$501,0))),"") | F16: =IFERROR(IF(INDEX(Itens!$I$2:$I$501,MATCH(4,Itens!$M$2:$M$501,0))="","",INDEX(Itens!$I$2:$I$501,MATCH(4,Itens!$M$2:$M$501,0))),"") | G16: =IFERROR(IF(INDEX(Itens!$J$2:$J$501,MATCH(4,Itens!$M$2:$M$501,0))="","",INDEX(Itens!$J$2:$J$501,MATCH(4,Itens!$M$2:$M$501,0))),"") | H16: =IFERROR(IF(INDEX(Itens!$K$2:$K$501,MATCH(4,Itens!$M$2:$M$501,0))="","",INDEX(Itens!$K$2:$K$501,MATCH(4,Itens!$M$2:$M$501,0))),"") | I16: =IFERROR(IF(INDEX(Itens!$L$2:$L$501,MATCH(4,Itens!$M$2:$M$501,0))="","",INDEX(Itens!$L$2:$L$501,MATCH(4,Itens!$M$2:$M$501,0))),"")
A17: =IFERROR(IF(INDEX(Itens!$A$2:$A$501,MATCH(5,Itens!$M$2:$M$501,0))="","",INDEX(Itens!$A$2:$A$501,MATCH(5,Itens!$M$2:$M$501,0))),"") | B17: =IFERROR(IF(INDEX(Itens!$C$2:$C$501,MATCH(5,Itens!$M$2:$M$501,0))="","",INDEX(Itens!$C$2:$C$501,MATCH(5,Itens!$M$2:$M$501,0))),"") | C17: =IFERROR(IF(INDEX(Itens!$E$2:$E$501,MATCH(5,Itens!$M$2:$M$501,0))="","",INDEX(Itens!$E$2:$E$501,MATCH(5,Itens!$M$2:$M$501,0))),"") | D17: =IFERROR(IF(INDEX(Itens!$F$2:$F$501,MATCH(5,Itens!$M$2:$M$501,0))="","",INDEX(Itens!$F$2:$F$501,MATCH(5,Itens!$M$2:$M$501,0))),"") | E17: =IFERROR(IF(INDEX(Itens!$G$2:$G$501,MATCH(5,Itens!$M$2:$M$501,0))="","",INDEX(Itens!$G$2:$G$501,MATCH(5,Itens!$M$2:$M$501,0))),"") | F17: =IFERROR(IF(INDEX(Itens!$I$2:$I$501,MATCH(5,Itens!$M$2:$M$501,0))="","",INDEX(Itens!$I$2:$I$501,MATCH(5,Itens!$M$2:$M$501,0))),"") | G17: =IFERROR(IF(INDEX(Itens!$J$2:$J$501,MATCH(5,Itens!$M$2:$M$501,0))="","",INDEX(Itens!$J$2:$J$501,MATCH(5,Itens!$M$2:$M$501,0))),"") | H17: =IFERROR(IF(INDEX(Itens!$K$2:$K$501,MATCH(5,Itens!$M$2:$M$501,0))="","",INDEX(Itens!$K$2:$K$501,MATCH(5,Itens!$M$2:$M$501,0))),"") | I17: =IFERROR(IF(INDEX(Itens!$L$2:$L$501,MATCH(5,Itens!$M$2:$M$501,0))="","",INDEX(Itens!$L$2:$L$501,MATCH(5,Itens!$M$2:$M$501,0))),"")
A18: =IFERROR(IF(INDEX(Itens!$A$2:$A$501,MATCH(6,Itens!$M$2:$M$501,0))="","",INDEX(Itens!$A$2:$A$501,MATCH(6,Itens!$M$2:$M$501,0))),"") | B18: =IFERROR(IF(INDEX(Itens!$C$2:$C$501,MATCH(6,Itens!$M$2:$M$501,0))="","",INDEX(Itens!$C$2:$C$501,MATCH(6,Itens!$M$2:$M$501,0))),"") | C18: =IFERROR(IF(INDEX(Itens!$E$2:$E$501,MATCH(6,Itens!$M$2:$M$501,0))="","",INDEX(Itens!$E$2:$E$501,MATCH(6,Itens!$M$2:$M$501,0))),"") | D18: =IFERROR(IF(INDEX(Itens!$F$2:$F$501,MATCH(6,Itens!$M$2:$M$501,0))="","",INDEX(Itens!$F$2:$F$501,MATCH(6,Itens!$M$2:$M$501,0))),"") | E18: =IFERROR(IF(INDEX(Itens!$G$2:$G$501,MATCH(6,Itens!$M$2:$M$501,0))="","",INDEX(Itens!$G$2:$G$501,MATCH(6,Itens!$M$2:$M$501,0))),"") | F18: =IFERROR(IF(INDEX(Itens!$I$2:$I$501,MATCH(6,Itens!$M$2:$M$501,0))="","",INDEX(Itens!$I$2:$I$501,MATCH(6,Itens!$M$2:$M$501,0))),"") | G18: =IFERROR(IF(INDEX(Itens!$J$2:$J$501,MATCH(6,Itens!$M$2:$M$501,0))="","",INDEX(Itens!$J$2:$J$501,MATCH(6,Itens!$M$2:$M$501,0))),"") | H18: =IFERROR(IF(INDEX(Itens!$K$2:$K$501,MATCH(6,Itens!$M$2:$M$501,0))="","",INDEX(Itens!$K$2:$K$501,MATCH(6,Itens!$M$2:$M$501,0))),"") | I18: =IFERROR(IF(INDEX(Itens!$L$2:$L$501,MATCH(6,Itens!$M$2:$M$501,0))="","",INDEX(Itens!$L$2:$L$501,MATCH(6,Itens!$M$2:$M$501,0))),"")
A19: =IFERROR(IF(INDEX(Itens!$A$2:$A$501,MATCH(7,Itens!$M$2:$M$501,0))="","",INDEX(Itens!$A$2:$A$501,MATCH(7,Itens!$M$2:$M$501,0))),"") | B19: =IFERROR(IF(INDEX(Itens!$C$2:$C$501,MATCH(7,Itens!$M$2:$M$501,0))="","",INDEX(Itens!$C$2:$C$501,MATCH(7,Itens!$M$2:$M$501,0))),"") | C19: =IFERROR(IF(INDEX(Itens!$E$2:$E$501,MATCH(7,Itens!$M$2:$M$501,0))="","",INDEX(Itens!$E$2:$E$501,MATCH(7,Itens!$M$2:$M$501,0))),"") | D19: =IFERROR(IF(INDEX(Itens!$F$2:$F$501,MATCH(7,Itens!$M$2:$M$501,0))="","",INDEX(Itens!$F$2:$F$501,MATCH(7,Itens!$M$2:$M$501,0))),"") | E19: =IFERROR(IF(INDEX(Itens!$G$2:$G$501,MATCH(7,Itens!$M$2:$M$501,0))="","",INDEX(Itens!$G$2:$G$501,MATCH(7,Itens!$M$2:$M$501,0))),"") | F19: =IFERROR(IF(INDEX(Itens!$I$2:$I$501,MATCH(7,Itens!$M$2:$M$501,0))="","",INDEX(Itens!$I$2:$I$501,MATCH(7,Itens!$M$2:$M$501,0))),"") | G19: =IFERROR(IF(INDEX(Itens!$J$2:$J$501,MATCH(7,Itens!$M$2:$M$501,0))="","",INDEX(Itens!$J$2:$J$501,MATCH(7,Itens!$M$2:$M$501,0))),"") | H19: =IFERROR(IF(INDEX(Itens!$K$2:$K$501,MATCH(7,Itens!$M$2:$M$501,0))="","",INDEX(Itens!$K$2:$K$501,MATCH(7,Itens!$M$2:$M$501,0))),"") | I19: =IFERROR(IF(INDEX(Itens!$L$2:$L$501,MATCH(7,Itens!$M$2:$M$501,0))="","",INDEX(Itens!$L$2:$L$501,MATCH(7,Itens!$M$2:$M$501,0))),"")
A20: =IFERROR(IF(INDEX(Itens!$A$2:$A$501,MATCH(8,Itens!$M$2:$M$501,0))="","",INDEX(Itens!$A$2:$A$501,MATCH(8,Itens!$M$2:$M$501,0))),"") | B20: =IFERROR(IF(INDEX(Itens!$C$2:$C$501,MATCH(8,Itens!$M$2:$M$501,0))="","",INDEX(Itens!$C$2:$C$501,MATCH(8,Itens!$M$2:$M$501,0))),"") | C20: =IFERROR(IF(INDEX(Itens!$E$2:$E$501,MATCH(8,Itens!$M$2:$M$501,0))="","",INDEX(Itens!$E$2:$E$501,MATCH(8,Itens!$M$2:$M$501,0))),"") | D20: =IFERROR(IF(INDEX(Itens!$F$2:$F$501,MATCH(8,Itens!$M$2:$M$501,0))="","",INDEX(Itens!$F$2:$F$501,MATCH(8,Itens!$M$2:$M$501,0))),"") | E20: =IFERROR(IF(INDEX(Itens!$G$2:$G$501,MATCH(8,Itens!$M$2:$M$501,0))="","",INDEX(Itens!$G$2:$G$501,MATCH(8,Itens!$M$2:$M$501,0))),"") | F20: =IFERROR(IF(INDEX(Itens!$I$2:$I$501,MATCH(8,Itens!$M$2:$M$501,0))="","",INDEX(Itens!$I$2:$I$501,MATCH(8,Itens!$M$2:$M$501,0))),"") | G20: =IFERROR(IF(INDEX(Itens!$J$2:$J$501,MATCH(8,Itens!$M$2:$M$501,0))="","",INDEX(Itens!$J$2:$J$501,MATCH(8,Itens!$M$2:$M$501,0))),"") | H20: =IFERROR(IF(INDEX(Itens!$K$2:$K$501,MATCH(8,Itens!$M$2:$M$501,0))="","",INDEX(Itens!$K$2:$K$501,MATCH(8,Itens!$M$2:$M$501,0))),"") | I20: =IFERROR(IF(INDEX(Itens!$L$2:$L$501,MATCH(8,Itens!$M$2:$M$501,0))="","",INDEX(Itens!$L$2:$L$501,MATCH(8,Itens!$M$2:$M$501,0))),"")
A21: =IFERROR(IF(INDEX(Itens!$A$2:$A$501,MATCH(9,Itens!$M$2:$M$501,0))="","",INDEX(Itens!$A$2:$A$501,MATCH(9,Itens!$M$2:$M$501,0))),"") | B21: =IFERROR(IF(INDEX(Itens!$C$2:$C$501,MATCH(9,Itens!$M$2:$M$501,0))="","",INDEX(Itens!$C$2:$C$501,MATCH(9,Itens!$M$2:$M$501,0))),"") | C21: =IFERROR(IF(INDEX(Itens!$E$2:$E$501,MATCH(9,Itens!$M$2:$M$501,0))="","",INDEX(Itens!$E$2:$E$501,MATCH(9,Itens!$M$2:$M$501,0))),"") | D21: =IFERROR(IF(INDEX(Itens!$F$2:$F$501,MATCH(9,Itens!$M$2:$M$501,0))="","",INDEX(Itens!$F$2:$F$501,MATCH(9,Itens!$M$2:$M$501,0))),"") | E21: =IFERROR(IF(INDEX(Itens!$G$2:$G$501,MATCH(9,Itens!$M$2:$M$501,0))="","",INDEX(Itens!$G$2:$G$501,MATCH(9,Itens!$M$2:$M$501,0))),"") | F21: =IFERROR(IF(INDEX(Itens!$I$2:$I$501,MATCH(9,Itens!$M$2:$M$501,0))="","",INDEX(Itens!$I$2:$I$501,MATCH(9,Itens!$M$2:$M$501,0))),"") | G21: =IFERROR(IF(INDEX(Itens!$J$2:$J$501,MATCH(9,Itens!$M$2:$M$501,0))="","",INDEX(Itens!$J$2:$J$501,MATCH(9,Itens!$M$2:$M$501,0))),"") | H21: =IFERROR(IF(INDEX(Itens!$K$2:$K$501,MATCH(9,Itens!$M$2:$M$501,0))="","",INDEX(Itens!$K$2:$K$501,MATCH(9,Itens!$M$2:$M$501,0))),"") | I21: =IFERROR(IF(INDEX(Itens!$L$2:$L$501,MATCH(9,Itens!$M$2:$M$501,0))="","",INDEX(Itens!$L$2:$L$501,MATCH(9,Itens!$M$2:$M$501,0))),"")
A22: =IFERROR(IF(INDEX(Itens!$A$2:$A$501,MATCH(10,Itens!$M$2:$M$501,0))="","",INDEX(Itens!$A$2:$A$501,MATCH(10,Itens!$M$2:$M$501,0))),"") | B22: =IFERROR(IF(INDEX(Itens!$C$2:$C$501,MATCH(10,Itens!$M$2:$M$501,0))="","",INDEX(Itens!$C$2:$C$501,MATCH(10,Itens!$M$2:$M$501,0))),"") | C22: =IFERROR(IF(INDEX(Itens!$E$2:$E$501,MATCH(10,Itens!$M$2:$M$501,0))="","",INDEX(Itens!$E$2:$E$501,MATCH(10,Itens!$M$2:$M$501,0))),"") | D22: =IFERROR(IF(INDEX(Itens!$F$2:$F$501,MATCH(10,Itens!$M$2:$M$501,0))="","",INDEX(Itens!$F$2:$F$501,MATCH(10,Itens!$M$2:$M$501,0))),"") | E22: =IFERROR(IF(INDEX(Itens!$G$2:$G$501,MATCH(10,Itens!$M$2:$M$501,0))="","",INDEX(Itens!$G$2:$G$501,MATCH(10,Itens!$M$2:$M$501,0))),"") | F22: =IFERROR(IF(INDEX(Itens!$I$2:$I$501,MATCH(10,Itens!$M$2:$M$501,0))="","",INDEX(Itens!$I$2:$I$501,MATCH(10,Itens!$M$2:$M$501,0))),"") | G22: =IFERROR(IF(INDEX(Itens!$J$2:$J$501,MATCH(10,Itens!$M$2:$M$501,0))="","",INDEX(Itens!$J$2:$J$501,MATCH(10,Itens!$M$2:$M$501,0))),"") | H22: =IFERROR(IF(INDEX(Itens!$K$2:$K$501,MATCH(10,Itens!$M$2:$M$501,0))="","",INDEX(Itens!$K$2:$K$501,MATCH(10,Itens!$M$2:$M$501,0))),"") | I22: =IFERROR(IF(INDEX(Itens!$L$2:$L$501,MATCH(10,Itens!$M$2:$M$501,0))="","",INDEX(Itens!$L$2:$L$501,MATCH(10,Itens!$M$2:$M$501,0))),"")
A23: =IFERROR(IF(INDEX(Itens!$A$2:$A$501,MATCH(11,Itens!$M$2:$M$501,0))="","",INDEX(Itens!$A$2:$A$501,MATCH(11,Itens!$M$2:$M$501,0))),"") | B23: =IFERROR(IF(INDEX(Itens!$C$2:$C$501,MATCH(11,Itens!$M$2:$M$501,0))="","",INDEX(Itens!$C$2:$C$501,MATCH(11,Itens!$M$2:$M$501,0))),"") | C23: =IFERROR(IF(INDEX(Itens!$E$2:$E$501,MATCH(11,Itens!$M$2:$M$501,0))="","",INDEX(Itens!$E$2:$E$501,MATCH(11,Itens!$M$2:$M$501,0))),"") | D23: =IFERROR(IF(INDEX(Itens!$F$2:$F$501,MATCH(11,Itens!$M$2:$M$501,0))="","",INDEX(Itens!$F$2:$F$501,MATCH(11,Itens!$M$2:$M$501,0))),"") | E23: =IFERROR(IF(INDEX(Itens!$G$2:$G$501,MATCH(11,Itens!$M$2:$M$501,0))="","",INDEX(Itens!$G$2:$G$501,MATCH(11,Itens!$M$2:$M$501,0))),"") | F23: =IFERROR(IF(INDEX(Itens!$I$2:$I$501,MATCH(11,Itens!$M$2:$M$501,0))="","",INDEX(Itens!$I$2:$I$501,MATCH(11,Itens!$M$2:$M$501,0))),"") | G23: =IFERROR(IF(INDEX(Itens!$J$2:$J$501,MATCH(11,Itens!$M$2:$M$501,0))="","",INDEX(Itens!$J$2:$J$501,MATCH(11,Itens!$M$2:$M$501,0))),"") | H23: =IFERROR(IF(INDEX(Itens!$K$2:$K$501,MATCH(11,Itens!$M$2:$M$501,0))="","",INDEX(Itens!$K$2:$K$501,MATCH(11,Itens!$M$2:$M$501,0))),"") | I23: =IFERROR(IF(INDEX(Itens!$L$2:$L$501,MATCH(11,Itens!$M$2:$M$501,0))="","",INDEX(Itens!$L$2:$L$501,MATCH(11,Itens!$M$2:$M$501,0))),"")
A24: =IFERROR(IF(INDEX(Itens!$A$2:$A$501,MATCH(12,Itens!$M$2:$M$501,0))="","",INDEX(Itens!$A$2:$A$501,MATCH(12,Itens!$M$2:$M$501,0))),"") | B24: =IFERROR(IF(INDEX(Itens!$C$2:$C$501,MATCH(12,Itens!$M$2:$M$501,0))="","",INDEX(Itens!$C$2:$C$501,MATCH(12,Itens!$M$2:$M$501,0))),"") | C24: =IFERROR(IF(INDEX(Itens!$E$2:$E$501,MATCH(12,Itens!$M$2:$M$501,0))="","",INDEX(Itens!$E$2:$E$501,MATCH(12,Itens!$M$2:$M$501,0))),"") | D24: =IFERROR(IF(INDEX(Itens!$F$2:$F$501,MATCH(12,Itens!$M$2:$M$501,0))="","",INDEX(Itens!$F$2:$F$501,MATCH(12,Itens!$M$2:$M$501,0))),"") | E24: =IFERROR(IF(INDEX(Itens!$G$2:$G$501,MATCH(12,Itens!$M$2:$M$501,0))="","",INDEX(Itens!$G$2:$G$501,MATCH(12,Itens!$M$2:$M$501,0))),"") | F24: =IFERROR(IF(INDEX(Itens!$I$2:$I$501,MATCH(12,Itens!$M$2:$M$501,0))="","",INDEX(Itens!$I$2:$I$501,MATCH(12,Itens!$M$2:$M$501,0))),"") | G24: =IFERROR(IF(INDEX(Itens!$J$2:$J$501,MATCH(12,Itens!$M$2:$M$501,0))="","",INDEX(Itens!$J$2:$J$501,MATCH(12,Itens!$M$2:$M$501,0))),"") | H24: =IFERROR(IF(INDEX(Itens!$K$2:$K$501,MATCH(12,Itens!$M$2:$M$501,0))="","",INDEX(Itens!$K$2:$K$501,MATCH(12,Itens!$M$2:$M$501,0))),"") | I24: =IFERROR(IF(INDEX(Itens!$L$2:$L$501,MATCH(12,Itens!$M$2:$M$501,0))="","",INDEX(Itens!$L$2:$L$501,MATCH(12,Itens!$M$2:$M$501,0))),"")
A25: =IFERROR(IF(INDEX(Itens!$A$2:$A$501,MATCH(13,Itens!$M$2:$M$501,0))="","",INDEX(Itens!$A$2:$A$501,MATCH(13,Itens!$M$2:$M$501,0))),"") | B25: =IFERROR(IF(INDEX(Itens!$C$2:$C$501,MATCH(13,Itens!$M$2:$M$501,0))="","",INDEX(Itens!$C$2:$C$501,MATCH(13,Itens!$M$2:$M$501,0))),"") | C25: =IFERROR(IF(INDEX(Itens!$E$2:$E$501,MATCH(13,Itens!$M$2:$M$501,0))="","",INDEX(Itens!$E$2:$E$501,MATCH(13,Itens!$M$2:$M$501,0))),"") | D25: =IFERROR(IF(INDEX(Itens!$F$2:$F$501,MATCH(13,Itens!$M$2:$M$501,0))="","",INDEX(Itens!$F$2:$F$501,MATCH(13,Itens!$M$2:$M$501,0))),"") | E25: =IFERROR(IF(INDEX(Itens!$G$2:$G$501,MATCH(13,Itens!$M$2:$M$501,0))="","",INDEX(Itens!$G$2:$G$501,MATCH(13,Itens!$M$2:$M$501,0))),"") | F25: =IFERROR(IF(INDEX(Itens!$I$2:$I$501,MATCH(13,Itens!$M$2:$M$501,0))="","",INDEX(Itens!$I$2:$I$501,MATCH(13,Itens!$M$2:$M$501,0))),"") | G25: =IFERROR(IF(INDEX(Itens!$J$2:$J$501,MATCH(13,Itens!$M$2:$M$501,0))="","",INDEX(Itens!$J$2:$J$501,MATCH(13,Itens!$M$2:$M$501,0))),"") | H25: =IFERROR(IF(INDEX(Itens!$K$2:$K$501,MATCH(13,Itens!$M$2:$M$501,0))="","",INDEX(Itens!$K$2:$K$501,MATCH(13,Itens!$M$2:$M$501,0))),"") | I25: =IFERROR(IF(INDEX(Itens!$L$2:$L$501,MATCH(13,Itens!$M$2:$M$501,0))="","",INDEX(Itens!$L$2:$L$501,MATCH(13,Itens!$M$2:$M$501,0))),"")
A26: =IFERROR(IF(INDEX(Itens!$A$2:$A$501,MATCH(14,Itens!$M$2:$M$501,0))="","",INDEX(Itens!$A$2:$A$501,MATCH(14,Itens!$M$2:$M$501,0))),"") | B26: =IFERROR(IF(INDEX(Itens!$C$2:$C$501,MATCH(14,Itens!$M$2:$M$501,0))="","",INDEX(Itens!$C$2:$C$501,MATCH(14,Itens!$M$2:$M$501,0))),"") | C26: =IFERROR(IF(INDEX(Itens!$E$2:$E$501,MATCH(14,Itens!$M$2:$M$501,0))="","",INDEX(Itens!$E$2:$E$501,MATCH(14,Itens!$M$2:$M$501,0))),"") | D26: =IFERROR(IF(INDEX(Itens!$F$2:$F$501,MATCH(14,Itens!$M$2:$M$501,0))="","",INDEX(Itens!$F$2:$F$501,MATCH(14,Itens!$M$2:$M$501,0))),"") | E26: =IFERROR(IF(INDEX(Itens!$G$2:$G$501,MATCH(14,Itens!$M$2:$M$501,0))="","",INDEX(Itens!$G$2:$G$501,MATCH(14,Itens!$M$2:$M$501,0))),"") | F26: =IFERROR(IF(INDEX(Itens!$I$2:$I$501,MATCH(14,Itens!$M$2:$M$501,0))="","",INDEX(Itens!$I$2:$I$501,MATCH(14,Itens!$M$2:$M$501,0))),"") | G26: =IFERROR(IF(INDEX(Itens!$J$2:$J$501,MATCH(14,Itens!$M$2:$M$501,0))="","",INDEX(Itens!$J$2:$J$501,MATCH(14,Itens!$M$2:$M$501,0))),"") | H26: =IFERROR(IF(INDEX(Itens!$K$2:$K$501,MATCH(14,Itens!$M$2:$M$501,0))="","",INDEX(Itens!$K$2:$K$501,MATCH(14,Itens!$M$2:$M$501,0))),"") | I26: =IFERROR(IF(INDEX(Itens!$L$2:$L$501,MATCH(14,Itens!$M$2:$M$501,0))="","",INDEX(Itens!$L$2:$L$501,MATCH(14,Itens!$M$2:$M$501,0))),"")
A27: =IFERROR(IF(INDEX(Itens!$A$2:$A$501,MATCH(15,Itens!$M$2:$M$501,0))="","",INDEX(Itens!$A$2:$A$501,MATCH(15,Itens!$M$2:$M$501,0))),"") | B27: =IFERROR(IF(INDEX(Itens!$C$2:$C$501,MATCH(15,Itens!$M$2:$M$501,0))="","",INDEX(Itens!$C$2:$C$501,MATCH(15,Itens!$M$2:$M$501,0))),"") | C27: =IFERROR(IF(INDEX(Itens!$E$2:$E$501,MATCH(15,Itens!$M$2:$M$501,0))="","",INDEX(Itens!$E$2:$E$501,MATCH(15,Itens!$M$2:$M$501,0))),"") | D27: =IFERROR(IF(INDEX(Itens!$F$2:$F$501,MATCH(15,Itens!$M$2:$M$501,0))="","",INDEX(Itens!$F$2:$F$501,MATCH(15,Itens!$M$2:$M$501,0))),"") | E27: =IFERROR(IF(INDEX(Itens!$G$2:$G$501,MATCH(15,Itens!$M$2:$M$501,0))="","",INDEX(Itens!$G$2:$G$501,MATCH(15,Itens!$M$2:$M$501,0))),"") | F27: =IFERROR(IF(INDEX(Itens!$I$2:$I$501,MATCH(15,Itens!$M$2:$M$501,0))="","",INDEX(Itens!$I$2:$I$501,MATCH(15,Itens!$M$2:$M$501,0))),"") | G27: =IFERROR(IF(INDEX(Itens!$J$2:$J$501,MATCH(15,Itens!$M$2:$M$501,0))="","",INDEX(Itens!$J$2:$J$501,MATCH(15,Itens!$M$2:$M$501,0))),"") | H27: =IFERROR(IF(INDEX(Itens!$K$2:$K$501,MATCH(15,Itens!$M$2:$M$501,0))="","",INDEX(Itens!$K$2:$K$501,MATCH(15,Itens!$M$2:$M$501,0))),"") | I27: =IFERROR(IF(INDEX(Itens!$L$2:$L$501,MATCH(15,Itens!$M$2:$M$501,0))="","",INDEX(Itens!$L$2:$L$501,MATCH(15,Itens!$M$2:$M$501,0))),"")
A28: =IFERROR(IF(INDEX(Itens!$A$2:$A$501,MATCH(16,Itens!$M$2:$M$501,0))="","",INDEX(Itens!$A$2:$A$501,MATCH(16,Itens!$M$2:$M$501,0))),"") | B28: =IFERROR(IF(INDEX(Itens!$C$2:$C$501,MATCH(16,Itens!$M$2:$M$501,0))="","",INDEX(Itens!$C$2:$C$501,MATCH(16,Itens!$M$2:$M$501,0))),"") | C28: =IFERROR(IF(INDEX(Itens!$E$2:$E$501,MATCH(16,Itens!$M$2:$M$501,0))="","",INDEX(Itens!$E$2:$E$501,MATCH(16,Itens!$M$2:$M$501,0))),"") | D28: =IFERROR(IF(INDEX(Itens!$F$2:$F$501,MATCH(16,Itens!$M$2:$M$501,0))="","",INDEX(Itens!$F$2:$F$501,MATCH(16,Itens!$M$2:$M$501,0))),"") | E28: =IFERROR(IF(INDEX(Itens!$G$2:$G$501,MATCH(16,Itens!$M$2:$M$501,0))="","",INDEX(Itens!$G$2:$G$501,MATCH(16,Itens!$M$2:$M$501,0))),"") | F28: =IFERROR(IF(INDEX(Itens!$I$2:$I$501,MATCH(16,Itens!$M$2:$M$501,0))="","",INDEX(Itens!$I$2:$I$501,MATCH(16,Itens!$M$2:$M$501,0))),"") | G28: =IFERROR(IF(INDEX(Itens!$J$2:$J$501,MATCH(16,Itens!$M$2:$M$501,0))="","",INDEX(Itens!$J$2:$J$501,MATCH(16,Itens!$M$2:$M$501,0))),"") | H28: =IFERROR(IF(INDEX(Itens!$K$2:$K$501,MATCH(16,Itens!$M$2:$M$501,0))="","",INDEX(Itens!$K$2:$K$501,MATCH(16,Itens!$M$2:$M$501,0))),"") | I28: =IFERROR(IF(INDEX(Itens!$L$2:$L$501,MATCH(16,Itens!$M$2:$M$501,0))="","",INDEX(Itens!$L$2:$L$501,MATCH(16,Itens!$M$2:$M$501,0))),"")
A29: =IFERROR(IF(INDEX(Itens!$A$2:$A$501,MATCH(17,Itens!$M$2:$M$501,0))="","",INDEX(Itens!$A$2:$A$501,MATCH(17,Itens!$M$2:$M$501,0))),"") | B29: =IFERROR(IF(INDEX(Itens!$C$2:$C$501,MATCH(17,Itens!$M$2:$M$501,0))="","",INDEX(Itens!$C$2:$C$501,MATCH(17,Itens!$M$2:$M$501,0))),"") | C29: =IFERROR(IF(INDEX(Itens!$E$2:$E$501,MATCH(17,Itens!$M$2:$M$501,0))="","",INDEX(Itens!$E$2:$E$501,MATCH(17,Itens!$M$2:$M$501,0))),"") | D29: =IFERROR(IF(INDEX(Itens!$F$2:$F$501,MATCH(17,Itens!$M$2:$M$501,0))="","",INDEX(Itens!$F$2:$F$501,MATCH(17,Itens!$M$2:$M$501,0))),"") | E29: =IFERROR(IF(INDEX(Itens!$G$2:$G$501,MATCH(17,Itens!$M$2:$M$501,0))="","",INDEX(Itens!$G$2:$G$501,MATCH(17,Itens!$M$2:$M$501,0))),"") | F29: =IFERROR(IF(INDEX(Itens!$I$2:$I$501,MATCH(17,Itens!$M$2:$M$501,0))="","",INDEX(Itens!$I$2:$I$501,MATCH(17,Itens!$M$2:$M$501,0))),"") | G29: =IFERROR(IF(INDEX(Itens!$J$2:$J$501,MATCH(17,Itens!$M$2:$M$501,0))="","",INDEX(Itens!$J$2:$J$501,MATCH(17,Itens!$M$2:$M$501,0))),"") | H29: =IFERROR(IF(INDEX(Itens!$K$2:$K$501,MATCH(17,Itens!$M$2:$M$501,0))="","",INDEX(Itens!$K$2:$K$501,MATCH(17,Itens!$M$2:$M$501,0))),"") | I29: =IFERROR(IF(INDEX(Itens!$L$2:$L$501,MATCH(17,Itens!$M$2:$M$501,0))="","",INDEX(Itens!$L$2:$L$501,MATCH(17,Itens!$M$2:$M$501,0))),"")
A30: =IFERROR(IF(INDEX(Itens!$A$2:$A$501,MATCH(18,Itens!$M$2:$M$501,0))="","",INDEX(Itens!$A$2:$A$501,MATCH(18,Itens!$M$2:$M$501,0))),"") | B30: =IFERROR(IF(INDEX(Itens!$C$2:$C$501,MATCH(18,Itens!$M$2:$M$501,0))="","",INDEX(Itens!$C$2:$C$501,MATCH(18,Itens!$M$2:$M$501,0))),"") | C30: =IFERROR(IF(INDEX(Itens!$E$2:$E$501,MATCH(18,Itens!$M$2:$M$501,0))="","",INDEX(Itens!$E$2:$E$501,MATCH(18,Itens!$M$2:$M$501,0))),"") | D30: =IFERROR(IF(INDEX(Itens!$F$2:$F$501,MATCH(18,Itens!$M$2:$M$501,0))="","",INDEX(Itens!$F$2:$F$501,MATCH(18,Itens!$M$2:$M$501,0))),"") | E30: =IFERROR(IF(INDEX(Itens!$G$2:$G$501,MATCH(18,Itens!$M$2:$M$501,0))="","",INDEX(Itens!$G$2:$G$501,MATCH(18,Itens!$M$2:$M$501,0))),"") | F30: =IFERROR(IF(INDEX(Itens!$I$2:$I$501,MATCH(18,Itens!$M$2:$M$501,0))="","",INDEX(Itens!$I$2:$I$501,MATCH(18,Itens!$M$2:$M$501,0))),"") | G30: =IFERROR(IF(INDEX(Itens!$J$2:$J$501,MATCH(18,Itens!$M$2:$M$501,0))="","",INDEX(Itens!$J$2:$J$501,MATCH(18,Itens!$M$2:$M$501,0))),"") | H30: =IFERROR(IF(INDEX(Itens!$K$2:$K$501,MATCH(18,Itens!$M$2:$M$501,0))="","",INDEX(Itens!$K$2:$K$501,MATCH(18,Itens!$M$2:$M$501,0))),"") | I30: =IFERROR(IF(INDEX(Itens!$L$2:$L$501,MATCH(18,Itens!$M$2:$M$501,0))="","",INDEX(Itens!$L$2:$L$501,MATCH(18,Itens!$M$2:$M$501,0))),"")
A31: =IFERROR(IF(INDEX(Itens!$A$2:$A$501,MATCH(19,Itens!$M$2:$M$501,0))="","",INDEX(Itens!$A$2:$A$501,MATCH(19,Itens!$M$2:$M$501,0))),"") | B31: =IFERROR(IF(INDEX(Itens!$C$2:$C$501,MATCH(19,Itens!$M$2:$M$501,0))="","",INDEX(Itens!$C$2:$C$501,MATCH(19,Itens!$M$2:$M$501,0))),"") | C31: =IFERROR(IF(INDEX(Itens!$E$2:$E$501,MATCH(19,Itens!$M$2:$M$501,0))="","",INDEX(Itens!$E$2:$E$501,MATCH(19,Itens!$M$2:$M$501,0))),"") | D31: =IFERROR(IF(INDEX(Itens!$F$2:$F$501,MATCH(19,Itens!$M$2:$M$501,0))="","",INDEX(Itens!$F$2:$F$501,MATCH(19,Itens!$M$2:$M$501,0))),"") | E31: =IFERROR(IF(INDEX(Itens!$G$2:$G$501,MATCH(19,Itens!$M$2:$M$501,0))="","",INDEX(Itens!$G$2:$G$501,MATCH(19,Itens!$M$2:$M$501,0))),"") | F31: =IFERROR(IF(INDEX(Itens!$I$2:$I$501,MATCH(19,Itens!$M$2:$M$501,0))="","",INDEX(Itens!$I$2:$I$501,MATCH(19,Itens!$M$2:$M$501,0))),"") | G31: =IFERROR(IF(INDEX(Itens!$J$2:$J$501,MATCH(19,Itens!$M$2:$M$501,0))="","",INDEX(Itens!$J$2:$J$501,MATCH(19,Itens!$M$2:$M$501,0))),"") | H31: =IFERROR(IF(INDEX(Itens!$K$2:$K$501,MATCH(19,Itens!$M$2:$M$501,0))="","",INDEX(Itens!$K$2:$K$501,MATCH(19,Itens!$M$2:$M$501,0))),"") | I31: =IFERROR(IF(INDEX(Itens!$L$2:$L$501,MATCH(19,Itens!$M$2:$M$501,0))="","",INDEX(Itens!$L$2:$L$501,MATCH(19,Itens!$M$2:$M$501,0))),"")
A32: =IFERROR(IF(INDEX(Itens!$A$2:$A$501,MATCH(20,Itens!$M$2:$M$501,0))="","",INDEX(Itens!$A$2:$A$501,MATCH(20,Itens!$M$2:$M$501,0))),"") | B32: =IFERROR(IF(INDEX(Itens!$C$2:$C$501,MATCH(20,Itens!$M$2:$M$501,0))="","",INDEX(Itens!$C$2:$C$501,MATCH(20,Itens!$M$2:$M$501,0))),"") | C32: =IFERROR(IF(INDEX(Itens!$E$2:$E$501,MATCH(20,Itens!$M$2:$M$501,0))="","",INDEX(Itens!$E$2:$E$501,MATCH(20,Itens!$M$2:$M$501,0))),"") | D32: =IFERROR(IF(INDEX(Itens!$F$2:$F$501,MATCH(20,Itens!$M$2:$M$501,0))="","",INDEX(Itens!$F$2:$F$501,MATCH(20,Itens!$M$2:$M$501,0))),"") | E32: =IFERROR(IF(INDEX(Itens!$G$2:$G$501,MATCH(20,Itens!$M$2:$M$501,0))="","",INDEX(Itens!$G$2:$G$501,MATCH(20,Itens!$M$2:$M$501,0))),"") | F32: =IFERROR(IF(INDEX(Itens!$I$2:$I$501,MATCH(20,Itens!$M$2:$M$501,0))="","",INDEX(Itens!$I$2:$I$501,MATCH(20,Itens!$M$2:$M$501,0))),"") | G32: =IFERROR(IF(INDEX(Itens!$J$2:$J$501,MATCH(20,Itens!$M$2:$M$501,0))="","",INDEX(Itens!$J$2:$J$501,MATCH(20,Itens!$M$2:$M$501,0))),"") | H32: =IFERROR(IF(INDEX(Itens!$K$2:$K$501,MATCH(20,Itens!$M$2:$M$501,0))="","",INDEX(Itens!$K$2:$K$501,MATCH(20,Itens!$M$2:$M$501,0))),"") | I32: =IFERROR(IF(INDEX(Itens!$L$2:$L$501,MATCH(20,Itens!$M$2:$M$501,0))="","",INDEX(Itens!$L$2:$L$501,MATCH(20,Itens!$M$2:$M$501,0))),"")
A33: =IFERROR(IF(INDEX(Itens!$A$2:$A$501,MATCH(21,Itens!$M$2:$M$501,0))="","",INDEX(Itens!$A$2:$A$501,MATCH(21,Itens!$M$2:$M$501,0))),"") | B33: =IFERROR(IF(INDEX(Itens!$C$2:$C$501,MATCH(21,Itens!$M$2:$M$501,0))="","",INDEX(Itens!$C$2:$C$501,MATCH(21,Itens!$M$2:$M$501,0))),"") | C33: =IFERROR(IF(INDEX(Itens!$E$2:$E$501,MATCH(21,Itens!$M$2:$M$501,0))="","",INDEX(Itens!$E$2:$E$501,MATCH(21,Itens!$M$2:$M$501,0))),"") | D33: =IFERROR(IF(INDEX(Itens!$F$2:$F$501,MATCH(21,Itens!$M$2:$M$501,0))="","",INDEX(Itens!$F$2:$F$501,MATCH(21,Itens!$M$2:$M$501,0))),"") | E33: =IFERROR(IF(INDEX(Itens!$G$2:$G$501,MATCH(21,Itens!$M$2:$M$501,0))="","",INDEX(Itens!$G$2:$G$501,MATCH(21,Itens!$M$2:$M$501,0))),"") | F33: =IFERROR(IF(INDEX(Itens!$I$2:$I$501,MATCH(21,Itens!$M$2:$M$501,0))="","",INDEX(Itens!$I$2:$I$501,MATCH(21,Itens!$M$2:$M$501,0))),"") | G33: =IFERROR(IF(INDEX(Itens!$J$2:$J$501,MATCH(21,Itens!$M$2:$M$501,0))="","",INDEX(Itens!$J$2:$J$501,MATCH(21,Itens!$M$2:$M$501,0))),"") | H33: =IFERROR(IF(INDEX(Itens!$K$2:$K$501,MATCH(21,Itens!$M$2:$M$501,0))="","",INDEX(Itens!$K$2:$K$501,MATCH(21,Itens!$M$2:$M$501,0))),"") | I33: =IFERROR(IF(INDEX(Itens!$L$2:$L$501,MATCH(21,Itens!$M$2:$M$501,0))="","",INDEX(Itens!$L$2:$L$501,MATCH(21,Itens!$M$2:$M$501,0))),"")
A34: =IFERROR(IF(INDEX(Itens!$A$2:$A$501,MATCH(22,Itens!$M$2:$M$501,0))="","",INDEX(Itens!$A$2:$A$501,MATCH(22,Itens!$M$2:$M$501,0))),"") | B34: =IFERROR(IF(INDEX(Itens!$C$2:$C$501,MATCH(22,Itens!$M$2:$M$501,0))="","",INDEX(Itens!$C$2:$C$501,MATCH(22,Itens!$M$2:$M$501,0))),"") | C34: =IFERROR(IF(INDEX(Itens!$E$2:$E$501,MATCH(22,Itens!$M$2:$M$501,0))="","",INDEX(Itens!$E$2:$E$501,MATCH(22,Itens!$M$2:$M$501,0))),"") | D34: =IFERROR(IF(INDEX(Itens!$F$2:$F$501,MATCH(22,Itens!$M$2:$M$501,0))="","",INDEX(Itens!$F$2:$F$501,MATCH(22,Itens!$M$2:$M$501,0))),"") | E34: =IFERROR(IF(INDEX(Itens!$G$2:$G$501,MATCH(22,Itens!$M$2:$M$501,0))="","",INDEX(Itens!$G$2:$G$501,MATCH(22,Itens!$M$2:$M$501,0))),"") | F34: =IFERROR(IF(INDEX(Itens!$I$2:$I$501,MATCH(22,Itens!$M$2:$M$501,0))="","",INDEX(Itens!$I$2:$I$501,MATCH(22,Itens!$M$2:$M$501,0))),"") | G34: =IFERROR(IF(INDEX(Itens!$J$2:$J$501,MATCH(22,Itens!$M$2:$M$501,0))="","",INDEX(Itens!$J$2:$J$501,MATCH(22,Itens!$M$2:$M$501,0))),"") | H34: =IFERROR(IF(INDEX(Itens!$K$2:$K$501,MATCH(22,Itens!$M$2:$M$501,0))="","",INDEX(Itens!$K$2:$K$501,MATCH(22,Itens!$M$2:$M$501,0))),"") | I34: =IFERROR(IF(INDEX(Itens!$L$2:$L$501,MATCH(22,Itens!$M$2:$M$501,0))="","",INDEX(Itens!$L$2:$L$501,MATCH(22,Itens!$M$2:$M$501,0))),"")
A35: =IFERROR(IF(INDEX(Itens!$A$2:$A$501,MATCH(23,Itens!$M$2:$M$501,0))="","",INDEX(Itens!$A$2:$A$501,MATCH(23,Itens!$M$2:$M$501,0))),"") | B35: =IFERROR(IF(INDEX(Itens!$C$2:$C$501,MATCH(23,Itens!$M$2:$M$501,0))="","",INDEX(Itens!$C$2:$C$501,MATCH(23,Itens!$M$2:$M$501,0))),"") | C35: =IFERROR(IF(INDEX(Itens!$E$2:$E$501,MATCH(23,Itens!$M$2:$M$501,0))="","",INDEX(Itens!$E$2:$E$501,MATCH(23,Itens!$M$2:$M$501,0))),"") | D35: =IFERROR(IF(INDEX(Itens!$F$2:$F$501,MATCH(23,Itens!$M$2:$M$501,0))="","",INDEX(Itens!$F$2:$F$501,MATCH(23,Itens!$M$2:$M$501,0))),"") | E35: =IFERROR(IF(INDEX(Itens!$G$2:$G$501,MATCH(23,Itens!$M$2:$M$501,0))="","",INDEX(Itens!$G$2:$G$501,MATCH(23,Itens!$M$2:$M$501,0))),"") | F35: =IFERROR(IF(INDEX(Itens!$I$2:$I$501,MATCH(23,Itens!$M$2:$M$501,0))="","",INDEX(Itens!$I$2:$I$501,MATCH(23,Itens!$M$2:$M$501,0))),"") | G35: =IFERROR(IF(INDEX(Itens!$J$2:$J$501,MATCH(23,Itens!$M$2:$M$501,0))="","",INDEX(Itens!$J$2:$J$501,MATCH(23,Itens!$M$2:$M$501,0))),"") | H35: =IFERROR(IF(INDEX(Itens!$K$2:$K$501,MATCH(23,Itens!$M$2:$M$501,0))="","",INDEX(Itens!$K$2:$K$501,MATCH(23,Itens!$M$2:$M$501,0))),"") | I35: =IFERROR(IF(INDEX(Itens!$L$2:$L$501,MATCH(23,Itens!$M$2:$M$501,0))="","",INDEX(Itens!$L$2:$L$501,MATCH(23,Itens!$M$2:$M$501,0))),"")
A36: =IFERROR(IF(INDEX(Itens!$A$2:$A$501,MATCH(24,Itens!$M$2:$M$501,0))="","",INDEX(Itens!$A$2:$A$501,MATCH(24,Itens!$M$2:$M$501,0))),"") | B36: =IFERROR(IF(INDEX(Itens!$C$2:$C$501,MATCH(24,Itens!$M$2:$M$501,0))="","",INDEX(Itens!$C$2:$C$501,MATCH(24,Itens!$M$2:$M$501,0))),"") | C36: =IFERROR(IF(INDEX(Itens!$E$2:$E$501,MATCH(24,Itens!$M$2:$M$501,0))="","",INDEX(Itens!$E$2:$E$501,MATCH(24,Itens!$M$2:$M$501,0))),"") | D36: =IFERROR(IF(INDEX(Itens!$F$2:$F$501,MATCH(24,Itens!$M$2:$M$501,0))="","",INDEX(Itens!$F$2:$F$501,MATCH(24,Itens!$M$2:$M$501,0))),"") | E36: =IFERROR(IF(INDEX(Itens!$G$2:$G$501,MATCH(24,Itens!$M$2:$M$501,0))="","",INDEX(Itens!$G$2:$G$501,MATCH(24,Itens!$M$2:$M$501,0))),"") | F36: =IFERROR(IF(INDEX(Itens!$I$2:$I$501,MATCH(24,Itens!$M$2:$M$501,0))="","",INDEX(Itens!$I$2:$I$501,MATCH(24,Itens!$M$2:$M$501,0))),"") | G36: =IFERROR(IF(INDEX(Itens!$J$2:$J$501,MATCH(24,Itens!$M$2:$M$501,0))="","",INDEX(Itens!$J$2:$J$501,MATCH(24,Itens!$M$2:$M$501,0))),"") | H36: =IFERROR(IF(INDEX(Itens!$K$2:$K$501,MATCH(24,Itens!$M$2:$M$501,0))="","",INDEX(Itens!$K$2:$K$501,MATCH(24,Itens!$M$2:$M$501,0))),"") | I36: =IFERROR(IF(INDEX(Itens!$L$2:$L$501,MATCH(24,Itens!$M$2:$M$501,0))="","",INDEX(Itens!$L$2:$L$501,MATCH(24,Itens!$M$2:$M$501,0))),"")
A37: =IFERROR(IF(INDEX(Itens!$A$2:$A$501,MATCH(25,Itens!$M$2:$M$501,0))="","",INDEX(Itens!$A$2:$A$501,MATCH(25,Itens!$M$2:$M$501,0))),"") | B37: =IFERROR(IF(INDEX(Itens!$C$2:$C$501,MATCH(25,Itens!$M$2:$M$501,0))="","",INDEX(Itens!$C$2:$C$501,MATCH(25,Itens!$M$2:$M$501,0))),"") | C37: =IFERROR(IF(INDEX(Itens!$E$2:$E$501,MATCH(25,Itens!$M$2:$M$501,0))="","",INDEX(Itens!$E$2:$E$501,MATCH(25,Itens!$M$2:$M$501,0))),"") | D37: =IFERROR(IF(INDEX(Itens!$F$2:$F$501,MATCH(25,Itens!$M$2:$M$501,0))="","",INDEX(Itens!$F$2:$F$501,MATCH(25,Itens!$M$2:$M$501,0))),"") | E37: =IFERROR(IF(INDEX(Itens!$G$2:$G$501,MATCH(25,Itens!$M$2:$M$501,0))="","",INDEX(Itens!$G$2:$G$501,MATCH(25,Itens!$M$2:$M$501,0))),"") | F37: =IFERROR(IF(INDEX(Itens!$I$2:$I$501,MATCH(25,Itens!$M$2:$M$501,0))="","",INDEX(Itens!$I$2:$I$501,MATCH(25,Itens!$M$2:$M$501,0))),"") | G37: =IFERROR(IF(INDEX(Itens!$J$2:$J$501,MATCH(25,Itens!$M$2:$M$501,0))="","",INDEX(Itens!$J$2:$J$501,MATCH(25,Itens!$M$2:$M$501,0))),"") | H37: =IFERROR(IF(INDEX(Itens!$K$2:$K$501,MATCH(25,Itens!$M$2:$M$501,0))="","",INDEX(Itens!$K$2:$K$501,MATCH(25,Itens!$M$2:$M$501,0))),"") | I37: =IFERROR(IF(INDEX(Itens!$L$2:$L$501,MATCH(25,Itens!$M$2:$M$501,0))="","",INDEX(Itens!$L$2:$L$501,MATCH(25,Itens!$M$2:$M$501,0))),"")
A38: =IFERROR(IF(INDEX(Itens!$A$2:$A$501,MATCH(26,Itens!$M$2:$M$501,0))="","",INDEX(Itens!$A$2:$A$501,MATCH(26,Itens!$M$2:$M$501,0))),"") | B38: =IFERROR(IF(INDEX(Itens!$C$2:$C$501,MATCH(26,Itens!$M$2:$M$501,0))="","",INDEX(Itens!$C$2:$C$501,MATCH(26,Itens!$M$2:$M$501,0))),"") | C38: =IFERROR(IF(INDEX(Itens!$E$2:$E$501,MATCH(26,Itens!$M$2:$M$501,0))="","",INDEX(Itens!$E$2:$E$501,MATCH(26,Itens!$M$2:$M$501,0))),"") | D38: =IFERROR(IF(INDEX(Itens!$F$2:$F$501,MATCH(26,Itens!$M$2:$M$501,0))="","",INDEX(Itens!$F$2:$F$501,MATCH(26,Itens!$M$2:$M$501,0))),"") | E38: =IFERROR(IF(INDEX(Itens!$G$2:$G$501,MATCH(26,Itens!$M$2:$M$501,0))="","",INDEX(Itens!$G$2:$G$501,MATCH(26,Itens!$M$2:$M$501,0))),"") | F38: =IFERROR(IF(INDEX(Itens!$I$2:$I$501,MATCH(26,Itens!$M$2:$M$501,0))="","",INDEX(Itens!$I$2:$I$501,MATCH(26,Itens!$M$2:$M$501,0))),"") | G38: =IFERROR(IF(INDEX(Itens!$J$2:$J$501,MATCH(26,Itens!$M$2:$M$501,0))="","",INDEX(Itens!$J$2:$J$501,MATCH(26,Itens!$M$2:$M$501,0))),"") | H38: =IFERROR(IF(INDEX(Itens!$K$2:$K$501,MATCH(26,Itens!$M$2:$M$501,0))="","",INDEX(Itens!$K$2:$K$501,MATCH(26,Itens!$M$2:$M$501,0))),"") | I38: =IFERROR(IF(INDEX(Itens!$L$2:$L$501,MATCH(26,Itens!$M$2:$M$501,0))="","",INDEX(Itens!$L$2:$L$501,MATCH(26,Itens!$M$2:$M$501,0))),"")
A39: =IFERROR(IF(INDEX(Itens!$A$2:$A$501,MATCH(27,Itens!$M$2:$M$501,0))="","",INDEX(Itens!$A$2:$A$501,MATCH(27,Itens!$M$2:$M$501,0))),"") | B39: =IFERROR(IF(INDEX(Itens!$C$2:$C$501,MATCH(27,Itens!$M$2:$M$501,0))="","",INDEX(Itens!$C$2:$C$501,MATCH(27,Itens!$M$2:$M$501,0))),"") | C39: =IFERROR(IF(INDEX(Itens!$E$2:$E$501,MATCH(27,Itens!$M$2:$M$501,0))="","",INDEX(Itens!$E$2:$E$501,MATCH(27,Itens!$M$2:$M$501,0))),"") | D39: =IFERROR(IF(INDEX(Itens!$F$2:$F$501,MATCH(27,Itens!$M$2:$M$501,0))="","",INDEX(Itens!$F$2:$F$501,MATCH(27,Itens!$M$2:$M$501,0))),"") | E39: =IFERROR(IF(INDEX(Itens!$G$2:$G$501,MATCH(27,Itens!$M$2:$M$501,0))="","",INDEX(Itens!$G$2:$G$501,MATCH(27,Itens!$M$2:$M$501,0))),"") | F39: =IFERROR(IF(INDEX(Itens!$I$2:$I$501,MATCH(27,Itens!$M$2:$M$501,0))="","",INDEX(Itens!$I$2:$I$501,MATCH(27,Itens!$M$2:$M$501,0))),"") | G39: =IFERROR(IF(INDEX(Itens!$J$2:$J$501,MATCH(27,Itens!$M$2:$M$501,0))="","",INDEX(Itens!$J$2:$J$501,MATCH(27,Itens!$M$2:$M$501,0))),"") | H39: =IFERROR(IF(INDEX(Itens!$K$2:$K$501,MATCH(27,Itens!$M$2:$M$501,0))="","",INDEX(Itens!$K$2:$K$501,MATCH(27,Itens!$M$2:$M$501,0))),"") | I39: =IFERROR(IF(INDEX(Itens!$L$2:$L$501,MATCH(27,Itens!$M$2:$M$501,0))="","",INDEX(Itens!$L$2:$L$501,MATCH(27,Itens!$M$2:$M$501,0))),"")
A40: =IFERROR(IF(INDEX(Itens!$A$2:$A$501,MATCH(28,Itens!$M$2:$M$501,0))="","",INDEX(Itens!$A$2:$A$501,MATCH(28,Itens!$M$2:$M$501,0))),"") | B40: =IFERROR(IF(INDEX(Itens!$C$2:$C$501,MATCH(28,Itens!$M$2:$M$501,0))="","",INDEX(Itens!$C$2:$C$501,MATCH(28,Itens!$M$2:$M$501,0))),"") | C40: =IFERROR(IF(INDEX(Itens!$E$2:$E$501,MATCH(28,Itens!$M$2:$M$501,0))="","",INDEX(Itens!$E$2:$E$501,MATCH(28,Itens!$M$2:$M$501,0))),"") | D40: =IFERROR(IF(INDEX(Itens!$F$2:$F$501,MATCH(28,Itens!$M$2:$M$501,0))="","",INDEX(Itens!$F$2:$F$501,MATCH(28,Itens!$M$2:$M$501,0))),"") | E40: =IFERROR(IF(INDEX(Itens!$G$2:$G$501,MATCH(28,Itens!$M$2:$M$501,0))="","",INDEX(Itens!$G$2:$G$501,MATCH(28,Itens!$M$2:$M$501,0))),"") | F40: =IFERROR(IF(INDEX(Itens!$I$2:$I$501,MATCH(28,Itens!$M$2:$M$501,0))="","",INDEX(Itens!$I$2:$I$501,MATCH(28,Itens!$M$2:$M$501,0))),"") | G40: =IFERROR(IF(INDEX(Itens!$J$2:$J$501,MATCH(28,Itens!$M$2:$M$501,0))="","",INDEX(Itens!$J$2:$J$501,MATCH(28,Itens!$M$2:$M$501,0))),"") | H40: =IFERROR(IF(INDEX(Itens!$K$2:$K$501,MATCH(28,Itens!$M$2:$M$501,0))="","",INDEX(Itens!$K$2:$K$501,MATCH(28,Itens!$M$2:$M$501,0))),"") | I40: =IFERROR(IF(INDEX(Itens!$L$2:$L$501,MATCH(28,Itens!$M$2:$M$501,0))="","",INDEX(Itens!$L$2:$L$501,MATCH(28,Itens!$M$2:$M$501,0))),"")
A41: =IFERROR(IF(INDEX(Itens!$A$2:$A$501,MATCH(29,Itens!$M$2:$M$501,0))="","",INDEX(Itens!$A$2:$A$501,MATCH(29,Itens!$M$2:$M$501,0))),"") | B41: =IFERROR(IF(INDEX(Itens!$C$2:$C$501,MATCH(29,Itens!$M$2:$M$501,0))="","",INDEX(Itens!$C$2:$C$501,MATCH(29,Itens!$M$2:$M$501,0))),"") | C41: =IFERROR(IF(INDEX(Itens!$E$2:$E$501,MATCH(29,Itens!$M$2:$M$501,0))="","",INDEX(Itens!$E$2:$E$501,MATCH(29,Itens!$M$2:$M$501,0))),"") | D41: =IFERROR(IF(INDEX(Itens!$F$2:$F$501,MATCH(29,Itens!$M$2:$M$501,0))="","",INDEX(Itens!$F$2:$F$501,MATCH(29,Itens!$M$2:$M$501,0))),"") | E41: =IFERROR(IF(INDEX(Itens!$G$2:$G$501,MATCH(29,Itens!$M$2:$M$501,0))="","",INDEX(Itens!$G$2:$G$501,MATCH(29,Itens!$M$2:$M$501,0))),"") | F41: =IFERROR(IF(INDEX(Itens!$I$2:$I$501,MATCH(29,Itens!$M$2:$M$501,0))="","",INDEX(Itens!$I$2:$I$501,MATCH(29,Itens!$M$2:$M$501,0))),"") | G41: =IFERROR(IF(INDEX(Itens!$J$2:$J$501,MATCH(29,Itens!$M$2:$M$501,0))="","",INDEX(Itens!$J$2:$J$501,MATCH(29,Itens!$M$2:$M$501,0))),"") | H41: =IFERROR(IF(INDEX(Itens!$K$2:$K$501,MATCH(29,Itens!$M$2:$M$501,0))="","",INDEX(Itens!$K$2:$K$501,MATCH(29,Itens!$M$2:$M$501,0))),"") | I41: =IFERROR(IF(INDEX(Itens!$L$2:$L$501,MATCH(29,Itens!$M$2:$M$501,0))="","",INDEX(Itens!$L$2:$L$501,MATCH(29,Itens!$M$2:$M$501,0))),"")
A42: =IFERROR(IF(INDEX(Itens!$A$2:$A$501,MATCH(30,Itens!$M$2:$M$501,0))="","",INDEX(Itens!$A$2:$A$501,MATCH(30,Itens!$M$2:$M$501,0))),"") | B42: =IFERROR(IF(INDEX(Itens!$C$2:$C$501,MATCH(30,Itens!$M$2:$M$501,0))="","",INDEX(Itens!$C$2:$C$501,MATCH(30,Itens!$M$2:$M$501,0))),"") | C42: =IFERROR(IF(INDEX(Itens!$E$2:$E$501,MATCH(30,Itens!$M$2:$M$501,0))="","",INDEX(Itens!$E$2:$E$501,MATCH(30,Itens!$M$2:$M$501,0))),"") | D42: =IFERROR(IF(INDEX(Itens!$F$2:$F$501,MATCH(30,Itens!$M$2:$M$501,0))="","",INDEX(Itens!$F$2:$F$501,MATCH(30,Itens!$M$2:$M$501,0))),"") | E42: =IFERROR(IF(INDEX(Itens!$G$2:$G$501,MATCH(30,Itens!$M$2:$M$501,0))="","",INDEX(Itens!$G$2:$G$501,MATCH(30,Itens!$M$2:$M$501,0))),"") | F42: =IFERROR(IF(INDEX(Itens!$I$2:$I$501,MATCH(30,Itens!$M$2:$M$501,0))="","",INDEX(Itens!$I$2:$I$501,MATCH(30,Itens!$M$2:$M$501,0))),"") | G42: =IFERROR(IF(INDEX(Itens!$J$2:$J$501,MATCH(30,Itens!$M$2:$M$501,0))="","",INDEX(Itens!$J$2:$J$501,MATCH(30,Itens!$M$2:$M$501,0))),"") | H42: =IFERROR(IF(INDEX(Itens!$K$2:$K$501,MATCH(30,Itens!$M$2:$M$501,0))="","",INDEX(Itens!$K$2:$K$501,MATCH(30,Itens!$M$2:$M$501,0))),"") | I42: =IFERROR(IF(INDEX(Itens!$L$2:$L$501,MATCH(30,Itens!$M$2:$M$501,0))="","",INDEX(Itens!$L$2:$L$501,MATCH(30,Itens!$M$2:$M$501,0))),"")
A43: =IFERROR(IF(INDEX(Itens!$A$2:$A$501,MATCH(31,Itens!$M$2:$M$501,0))="","",INDEX(Itens!$A$2:$A$501,MATCH(31,Itens!$M$2:$M$501,0))),"") | B43: =IFERROR(IF(INDEX(Itens!$C$2:$C$501,MATCH(31,Itens!$M$2:$M$501,0))="","",INDEX(Itens!$C$2:$C$501,MATCH(31,Itens!$M$2:$M$501,0))),"") | C43: =IFERROR(IF(INDEX(Itens!$E$2:$E$501,MATCH(31,Itens!$M$2:$M$501,0))="","",INDEX(Itens!$E$2:$E$501,MATCH(31,Itens!$M$2:$M$501,0))),"") | D43: =IFERROR(IF(INDEX(Itens!$F$2:$F$501,MATCH(31,Itens!$M$2:$M$501,0))="","",INDEX(Itens!$F$2:$F$501,MATCH(31,Itens!$M$2:$M$501,0))),"") | E43: =IFERROR(IF(INDEX(Itens!$G$2:$G$501,MATCH(31,Itens!$M$2:$M$501,0))="","",INDEX(Itens!$G$2:$G$501,MATCH(31,Itens!$M$2:$M$501,0))),"") | F43: =IFERROR(IF(INDEX(Itens!$I$2:$I$501,MATCH(31,Itens!$M$2:$M$501,0))="","",INDEX(Itens!$I$2:$I$501,MATCH(31,Itens!$M$2:$M$501,0))),"") | G43: =IFERROR(IF(INDEX(Itens!$J$2:$J$501,MATCH(31,Itens!$M$2:$M$501,0))="","",INDEX(Itens!$J$2:$J$501,MATCH(31,Itens!$M$2:$M$501,0))),"") | H43: =IFERROR(IF(INDEX(Itens!$K$2:$K$501,MATCH(31,Itens!$M$2:$M$501,0))="","",INDEX(Itens!$K$2:$K$501,MATCH(31,Itens!$M$2:$M$501,0))),"") | I43: =IFERROR(IF(INDEX(Itens!$L$2:$L$501,MATCH(31,Itens!$M$2:$M$501,0))="","",INDEX(Itens!$L$2:$L$501,MATCH(31,Itens!$M$2:$M$501,0))),"")
...

Sheet Catálogo
A1: Código | B1: Documento padrão | C1: Área | D1: Responsável | E1: Base legal | F1: Nº de notificações que pediram | G1: Nº total de itens | H1: Pendentes / a confirmar | I1: _chave ranking
A2: PGR | B2: PGR – inventário de riscos e plano de ação (por estabelecimento) | C2: SST | D2: Assessoria SST | E2: NR-01 | F2: =SUMIFS(Itens!$H:$H,Itens!$D:$D,A2) | G2: =COUNTIF(Itens!$D:$D,A2) | H2: =COUNTIFS(Itens!$D:$D,A2,Itens!$I:$I,"Pendente")+COUNTIFS(Itens!$D:$D,A2,Itens!$I:$I,"Em andamento")+COUNTIFS(Itens!$D:$D,A2,Itens!$I:$I,"A confirmar") | I2: =F2+G2/1000+(1000-ROW())/1000000
A3: PCMSO | B3: PCMSO + relatório analítico | C3: SST | D3: Assessoria SST | E3: NR-07 | F3: =SUMIFS(Itens!$H:$H,Itens!$D:$D,A3) | G3: =COUNTIF(Itens!$D:$D,A3) | H3: =COUNTIFS(Itens!$D:$D,A3,Itens!$I:$I,"Pendente")+COUNTIFS(Itens!$D:$D,A3,Itens!$I:$I,"Em andamento")+COUNTIFS(Itens!$D:$D,A3,Itens!$I:$I,"A confirmar") | I3: =F3+G3/1000+(1000-ROW())/1000000
A4: ASO | B4: ASOs (admissional, periódico, retorno, mudança de risco, demissional) | C4: SST | D4: Assessoria SST | E4: NR-07 | F4: =SUMIFS(Itens!$H:$H,Itens!$D:$D,A4) | G4: =COUNTIF(Itens!$D:$D,A4) | H4: =COUNTIFS(Itens!$D:$D,A4,Itens!$I:$I,"Pendente")+COUNTIFS(Itens!$D:$D,A4,Itens!$I:$I,"Em andamento")+COUNTIFS(Itens!$D:$D,A4,Itens!$I:$I,"A confirmar") | I4: =F4+G4/1000+(1000-ROW())/1000000
A5: EPI | B5: Fichas de entrega de EPI com CA válido (e comprovante de compra) | C5: SST | D5: Compartilhado (Empresa + SST) | E5: NR-06 | F5: =SUMIFS(Itens!$H:$H,Itens!$D:$D,A5) | G5: =COUNTIF(Itens!$D:$D,A5) | H5: =COUNTIFS(Itens!$D:$D,A5,Itens!$I:$I,"Pendente")+COUNTIFS(Itens!$D:$D,A5,Itens!$I:$I,"Em andamento")+COUNTIFS(Itens!$D:$D,A5,Itens!$I:$I,"A confirmar") | I5: =F5+G5/1000+(1000-ROW())/1000000
A6: CIPA | B6: CIPA – edital, eleição, posse, calendário, atas e treinamento | C6: SST | D6: Compartilhado (Empresa + SST) | E6: NR-05 | F6: =SUMIFS(Itens!$H:$H,Itens!$D:$D,A6) | G6: =COUNTIF(Itens!$D:$D,A6) | H6: =COUNTIFS(Itens!$D:$D,A6,Itens!$I:$I,"Pendente")+COUNTIFS(Itens!$D:$D,A6,Itens!$I:$I,"Em andamento")+COUNTIFS(Itens!$D:$D,A6,Itens!$I:$I,"A confirmar") | I6: =F6+G6/1000+(1000-ROW())/1000000
A7: NR05-DESIG | B7: Designado NR-05 – nomeação formal e certificado de treinamento | C7: SST | D7: Compartilhado (Empresa + SST) | E7: NR-05 (5.4.14 e 5.7) | F7: =SUMIFS(Itens!$H:$H,Itens!$D:$D,A7) | G7: =COUNTIF(Itens!$D:$D,A7) | H7: =COUNTIFS(Itens!$D:$D,A7,Itens!$I:$I,"Pendente")+COUNTIFS(Itens!$D:$D,A7,Itens!$I:$I,"Em andamento")+COUNTIFS(Itens!$D:$D,A7,Itens!$I:$I,"A confirmar") | I7: =F7+G7/1000+(1000-ROW())/1000000
A8: LTCAT | B8: LTCAT / laudo de insalubridade e periculosidade | C8: SST | D8: Assessoria SST | E8: NR-15, NR-16, Lei 8.213/91 | F8: =SUMIFS(Itens!$H:$H,Itens!$D:$D,A8) | G8: =COUNTIF(Itens!$D:$D,A8) | H8: =COUNTIFS(Itens!$D:$D,A8,Itens!$I:$I,"Pendente")+COUNTIFS(Itens!$D:$D,A8,Itens!$I:$I,"Em andamento")+COUNTIFS(Itens!$D:$D,A8,Itens!$I:$I,"A confirmar") | I8: =F8+G8/1000+(1000-ROW())/1000000
A9: AEP | B9: AEP/AET – avaliação ergonômica | C9: SST | D9: Assessoria SST | E9: NR-17 | F9: =SUMIFS(Itens!$H:$H,Itens!$D:$D,A9) | G9: =COUNTIF(Itens!$D:$D,A9) | H9: =COUNTIFS(Itens!$D:$D,A9,Itens!$I:$I,"Pendente")+COUNTIFS(Itens!$D:$D,A9,Itens!$I:$I,"Em andamento")+COUNTIFS(Itens!$D:$D,A9,Itens!$I:$I,"A confirmar") | I9: =F9+G9/1000+(1000-ROW())/1000000
A10: NR12-INV | B10: Inventário de máquinas e apreciação de riscos | C10: SST | D10: Assessoria SST | E10: NR-12 | F10: =SUMIFS(Itens!$H:$H,Itens!$D:$D,A10) | G10: =COUNTIF(Itens!$D:$D,A10) | H10: =COUNTIFS(Itens!$D:$D,A10,Itens!$I:$I,"Pendente")+COUNTIFS(Itens!$D:$D,A10,Itens!$I:$I,"Em andamento")+COUNTIFS(Itens!$D:$D,A10,Itens!$I:$I,"A confirmar") | I10: =F10+G10/1000+(1000-ROW())/1000000
A11: TREIN | B11: Certificados de treinamento/capacitação (máquinas, empilhadeira etc.) | C11: SST | D11: Assessoria SST | E11: NR-01, NR-11, NR-12 | F11: =SUMIFS(Itens!$H:$H,Itens!$D:$D,A11) | G11: =COUNTIF(Itens!$D:$D,A11) | H11: =COUNTIFS(Itens!$D:$D,A11,Itens!$I:$I,"Pendente")+COUNTIFS(Itens!$D:$D,A11,Itens!$I:$I,"Em andamento")+COUNTIFS(Itens!$D:$D,A11,Itens!$I:$I,"A confirmar") | I11: =F11+G11/1000+(1000-ROW())/1000000
A12: ACID | B12: Procedimento e análise de acidentes e doenças do trabalho | C12: SST | D12: Assessoria SST | E12: NR-01 | F12: =SUMIFS(Itens!$H:$H,Itens!$D:$D,A12) | G12: =COUNTIF(Itens!$D:$D,A12) | H12: =COUNTIFS(Itens!$D:$D,A12,Itens!$I:$I,"Pendente")+COUNTIFS(Itens!$D:$D,A12,Itens!$I:$I,"Em andamento")+COUNTIFS(Itens!$D:$D,A12,Itens!$I:$I,"A confirmar") | I12: =F12+G12/1000+(1000-ROW())/1000000
A13: CAT | B13: CATs dos últimos 5 anos e relatórios de investigação | C13: SST | D13: Compartilhado (Empresa + SST) | E13: Lei 8.213/91 art. 22; NR-01 | F13: =SUMIFS(Itens!$H:$H,Itens!$D:$D,A13) | G13: =COUNTIF(Itens!$D:$D,A13) | H13: =COUNTIFS(Itens!$D:$D,A13,Itens!$I:$I,"Pendente")+COUNTIFS(Itens!$D:$D,A13,Itens!$I:$I,"Em andamento")+COUNTIFS(Itens!$D:$D,A13,Itens!$I:$I,"A confirmar") | I13: =F13+G13/1000+(1000-ROW())/1000000
... A40: COMPARECER | B40: Comparecimento presencial (SRTE / MPT) | C40: Outros | D40: Compartilhado (Empresa + SST) | E40: — | F40: =SUMIFS(Itens!$H:$H,Itens!$D:$D,A40) | G40: =COUNTIF(Itens!$D:$D,A40) | H40: =COUNTIFS(Itens!$D:$D,A40,Itens!$I:$I,"Pendente")+COUNTIFS(Itens!$D:$D,A40,Itens!$I:$I,"Em andamento")+COUNTIFS(Itens!$D:$D,A40,Itens!$I:$I,"A confirmar") | I40: =F40+G40/1000+(1000-ROW())/1000000

Sheet Notificações
A1: ID | B1: Cliente | C1: Razão social | D1: CNPJ | E1: Estabelecimento / local | F1: Órgão | G1: Tipo | H1: Nº da notificação | I1: Processo / relatório | J1: Recebida em | K1: Prazo | L1: Dias para o prazo | M1: Meio de envio | N1: Auditor(es) / procurador | O1: Arquivo de origem | P1: Qualidade da leitura | Q1: Itens | R1: Itens pendentes / a confirmar | S1: Observações
A2: N-001 | B2: Rede Total (Mix Concórdia) | C2: MIX CONCORDIA COMERCIAL LTDA | D2: 38.493.415/0001-17 | E2: Av. Raul Seixas, 2602 – Santa Helena, Dias d'Ávila/BA | F2: MTE | G2: NAD | H2: 2LUHCWTBG9YZ5F | I2: Relatório de Inspeção 319087492 | J2: 45979 | K2: 45989 | L2: =IF(R2=0,"Concluída",K2-TODAY()) | M2: DET | N2: AFT Silvana Maria Cardim de Almeida e outros | O2: PDF escaneado (CamScanner) | P2: Boa | Q2: =COUNTIF(Itens!$A:$A,A2) | R2: =COUNTIFS(Itens!$A:$A,A2,Itens!$I:$I,"Pendente")+COUNTIFS(Itens!$A:$A,A2,Itens!$I:$I,"Em andamento")+COUNTIFS(Itens!$A:$A,A2,Itens!$I:$I,"A confirmar") | S2: Itens 27 a 30 manuscritos pelo auditor (exigências físicas, não só documentos).
